Workbook

Sheet Dashboard
A1: MtG Deck Master — Dashboard
A2: Live formulas over Master rows 5-601. Refreshes on recalculation. Built 2026-09-03.
Q3: Charts refresh with the tables (Excel recalculates on open).
A4: Deck | B4: Commander | C4: Target | D4: In box (target cards) | E4: Placeholders in box | F4: Box total | G4: Ordered (in transit) | H4: To Buy | I4: Complete % (in hand) | J4: Complete % (incl. ordered) | K4: $ To Buy (Base/Tuned target) | L4: $ Ordered value | M4: Box market value | N4: Target build value | O4: Tuned/B3 adds still To Buy
A5: D1 | B5: Quintorius Kand | C5: =SUM(Master!$M$5:$M$601) | D5: =SUMPRODUCT((Master!$M$5:$M$601<Master!$T$5:$T$601)*Master!$M$5:$M$601+(Master!$M$5:$M$601>=Master!$T$5:$T$601)*Master!$T$5:$T$601) | E5: =SUMPRODUCT((Master!$T$5:$T$601>Master!$M$5:$M$601)*(Master!$T$5:$T$601-Master!$M$5:$M$601)) | F5: =SUM(Master!$T$5:$T$601) | G5: =SUMPRODUCT((Master!$M$5:$M$601>Master!$T$5:$T$601)*(Master!$J$5:$J$601>=(Master!$M$5:$M$601-Master!$T$5:$T$601))*(Master!$M$5:$M$601-Master!$T$5:$T$601)) | H5: =SUMPRODUCT((Master!$M$5:$M$601>Master!$T$5:$T$601)*(Master!$J$5:$J$601<(Master!$M$5:$M$601-Master!$T$5:$T$601))*(Master!$M$5:$M$601-Master!$T$5:$T$601-Master!$J$5:$J$601)) | I5: =IFERROR(D5/C5,0) | J5: =IFERROR((D5+G5)/C5,0) | K5: =SUMPRODUCT((Master!$M$5:$M$601>Master!$T$5:$T$601)*(Master!$J$5:$J$601<(Master!$M$5:$M$601-Master!$T$5:$T$601))*(Master!$M$5:$M$601-Master!$T$5:$T$601-Master!$J$5:$J$601)*Master!$K$5:$K$601) | L5: =SUMPRODUCT((Master!$M$5:$M$601>Master!$T$5:$T$601)*(Master!$J$5:$J$601>=(Master!$M$5:$M$601-Master!$T$5:$T$601))*(Master!$M$5:$M$601-Master!$T$5:$T$601)*Master!$K$5:$K$601) | M5: =SUMPRODUCT(Master!$T$5:$T$601*Master!$K$5:$K$601) | N5: =SUMPRODUCT(Master!$M$5:$M$601*Master!$K$5:$K$601) | O5: =SUMPRODUCT((Master!$M$5:$M$601>0)*(Master!$D$5:$D$601="B3")*(Master!$B$5:$B$601="To Buy"))
A6: D2 | B6: Chulane | C6: =SUM(Master!$N$5:$N$601) | D6: =SUMPRODUCT((Master!$N$5:$N$601<Master!$U$5:$U$601)*Master!$N$5:$N$601+(Master!$N$5:$N$601>=Master!$U$5:$U$601)*Master!$U$5:$U$601) | E6: =SUMPRODUCT((Master!$U$5:$U$601>Master!$N$5:$N$601)*(Master!$U$5:$U$601-Master!$N$5:$N$601)) | F6: =SUM(Master!$U$5:$U$601) | G6: =SUMPRODUCT((Master!$N$5:$N$601>Master!$U$5:$U$601)*(Master!$J$5:$J$601>=(Master!$N$5:$N$601-Master!$U$5:$U$601))*(Master!$N$5:$N$601-Master!$U$5:$U$601)) | H6: =SUMPRODUCT((Master!$N$5:$N$601>Master!$U$5:$U$601)*(Master!$J$5:$J$601<(Master!$N$5:$N$601-Master!$U$5:$U$601))*(Master!$N$5:$N$601-Master!$U$5:$U$601-Master!$J$5:$J$601)) | I6: =IFERROR(D6/C6,0) | J6: =IFERROR((D6+G6)/C6,0) | K6: =SUMPRODUCT((Master!$N$5:$N$601>Master!$U$5:$U$601)*(Master!$J$5:$J$601<(Master!$N$5:$N$601-Master!$U$5:$U$601))*(Master!$N$5:$N$601-Master!$U$5:$U$601-Master!$J$5:$J$601)*Master!$K$5:$K$601) | L6: =SUMPRODUCT((Master!$N$5:$N$601>Master!$U$5:$U$601)*(Master!$J$5:$J$601>=(Master!$N$5:$N$601-Master!$U$5:$U$601))*(Master!$N$5:$N$601-Master!$U$5:$U$601)*Master!$K$5:$K$601) | M6: =SUMPRODUCT(Master!$U$5:$U$601*Master!$K$5:$K$601) | N6: =SUMPRODUCT(Master!$N$5:$N$601*Master!$K$5:$K$601) | O6: =SUMPRODUCT((Master!$N$5:$N$601>0)*(Master!$D$5:$D$601="B3")*(Master!$B$5:$B$601="To Buy"))
A7: D3 | B7: Atraxa | C7: =SUM(Master!$O$5:$O$601) | D7: =SUMPRODUCT((Master!$O$5:$O$601<Master!$V$5:$V$601)*Master!$O$5:$O$601+(Master!$O$5:$O$601>=Master!$V$5:$V$601)*Master!$V$5:$V$601) | E7: =SUMPRODUCT((Master!$V$5:$V$601>Master!$O$5:$O$601)*(Master!$V$5:$V$601-Master!$O$5:$O$601)) | F7: =SUM(Master!$V$5:$V$601) | G7: =SUMPRODUCT((Master!$O$5:$O$601>Master!$V$5:$V$601)*(Master!$J$5:$J$601>=(Master!$O$5:$O$601-Master!$V$5:$V$601))*(Master!$O$5:$O$601-Master!$V$5:$V$601)) | H7: =SUMPRODUCT((Master!$O$5:$O$601>Master!$V$5:$V$601)*(Master!$J$5:$J$601<(Master!$O$5:$O$601-Master!$V$5:$V$601))*(Master!$O$5:$O$601-Master!$V$5:$V$601-Master!$J$5:$J$601)) | I7: =IFERROR(D7/C7,0) | J7: =IFERROR((D7+G7)/C7,0) | K7: =SUMPRODUCT((Master!$O$5:$O$601>Master!$V$5:$V$601)*(Master!$J$5:$J$601<(Master!$O$5:$O$601-Master!$V$5:$V$601))*(Master!$O$5:$O$601-Master!$V$5:$V$601-Master!$J$5:$J$601)*Master!$K$5:$K$601) | L7: =SUMPRODUCT((Master!$O$5:$O$601>Master!$V$5:$V$601)*(Master!$J$5:$J$601>=(Master!$O$5:$O$601-Master!$V$5:$V$601))*(Master!$O$5:$O$601-Master!$V$5:$V$601)*Master!$K$5:$K$601) | M7: =SUMPRODUCT(Master!$V$5:$V$601*Master!$K$5:$K$601) | N7: =SUMPRODUCT(Master!$O$5:$O$601*Master!$K$5:$K$601) | O7: =SUMPRODUCT((Master!$O$5:$O$601>0)*(Master!$D$5:$D$601="B3")*(Master!$B$5:$B$601="To Buy"))
A8: D4 | B8: Betor | C8: =SUM(Master!$P$5:$P$601) | D8: =SUMPRODUCT((Master!$P$5:$P$601<Master!$W$5:$W$601)*Master!$P$5:$P$601+(Master!$P$5:$P$601>=Master!$W$5:$W$601)*Master!$W$5:$W$601) | E8: =SUMPRODUCT((Master!$W$5:$W$601>Master!$P$5:$P$601)*(Master!$W$5:$W$601-Master!$P$5:$P$601)) | F8: =SUM(Master!$W$5:$W$601) | G8: =SUMPRODUCT((Master!$P$5:$P$601>Master!$W$5:$W$601)*(Master!$J$5:$J$601>=(Master!$P$5:$P$601-Master!$W$5:$W$601))*(Master!$P$5:$P$601-Master!$W$5:$W$601)) | H8: =SUMPRODUCT((Master!$P$5:$P$601>Master!$W$5:$W$601)*(Master!$J$5:$J$601<(Master!$P$5:$P$601-Master!$W$5:$W$601))*(Master!$P$5:$P$601-Master!$W$5:$W$601-Master!$J$5:$J$601)) | I8: =IFERROR(D8/C8,0) | J8: =IFERROR((D8+G8)/C8,0) | K8: =SUMPRODUCT((Master!$P$5:$P$601>Master!$W$5:$W$601)*(Master!$J$5:$J$601<(Master!$P$5:$P$601-Master!$W$5:$W$601))*(Master!$P$5:$P$601-Master!$W$5:$W$601-Master!$J$5:$J$601)*Master!$K$5:$K$601) | L8: =SUMPRODUCT((Master!$P$5:$P$601>Master!$W$5:$W$601)*(Master!$J$5:$J$601>=(Master!$P$5:$P$601-Master!$W$5:$W$601))*(Master!$P$5:$P$601-Master!$W$5:$W$601)*Master!$K$5:$K$601) | M8: =SUMPRODUCT(Master!$W$5:$W$601*Master!$K$5:$K$601) | N8: =SUMPRODUCT(Master!$P$5:$P$601*Master!$K$5:$K$601) | O8: =SUMPRODUCT((Master!$P$5:$P$601>0)*(Master!$D$5:$D$601="B3")*(Master!$B$5:$B$601="To Buy"))
A9: D5 | B9: Shadrix | C9: =SUM(Master!$Q$5:$Q$601) | D9: =SUMPRODUCT((Master!$Q$5:$Q$601<Master!$X$5:$X$601)*Master!$Q$5:$Q$601+(Master!$Q$5:$Q$601>=Master!$X$5:$X$601)*Master!$X$5:$X$601) | E9: =SUMPRODUCT((Master!$X$5:$X$601>Master!$Q$5:$Q$601)*(Master!$X$5:$X$601-Master!$Q$5:$Q$601)) | F9: =SUM(Master!$X$5:$X$601) | G9: =SUMPRODUCT((Master!$Q$5:$Q$601>Master!$X$5:$X$601)*(Master!$J$5:$J$601>=(Master!$Q$5:$Q$601-Master!$X$5:$X$601))*(Master!$Q$5:$Q$601-Master!$X$5:$X$601)) | H9: =SUMPRODUCT((Master!$Q$5:$Q$601>Master!$X$5:$X$601)*(Master!$J$5:$J$601<(Master!$Q$5:$Q$601-Master!$X$5:$X$601))*(Master!$Q$5:$Q$601-Master!$X$5:$X$601-Master!$J$5:$J$601)) | I9: =IFERROR(D9/C9,0) | J9: =IFERROR((D9+G9)/C9,0) | K9: =SUMPRODUCT((Master!$Q$5:$Q$601>Master!$X$5:$X$601)*(Master!$J$5:$J$601<(Master!$Q$5:$Q$601-Master!$X$5:$X$601))*(Master!$Q$5:$Q$601-Master!$X$5:$X$601-Master!$J$5:$J$601)*Master!$K$5:$K$601) | L9: =SUMPRODUCT((Master!$Q$5:$Q$601>Master!$X$5:$X$601)*(Master!$J$5:$J$601>=(Master!$Q$5:$Q$601-Master!$X$5:$X$601))*(Master!$Q$5:$Q$601-Master!$X$5:$X$601)*Master!$K$5:$K$601) | M9: =SUMPRODUCT(Master!$X$5:$X$601*Master!$K$5:$K$601) | N9: =SUMPRODUCT(Master!$Q$5:$Q$601*Master!$K$5:$K$601) | O9: =SUMPRODUCT((Master!$Q$5:$Q$601>0)*(Master!$D$5:$D$601="B3")*(Master!$B$5:$B$601="To Buy"))
A10: D6 | B10: Purphoros | C10: =SUM(Master!$R$5:$R$601) | D10: =SUMPRODUCT((Master!$R$5:$R$601<Master!$Y$5:$Y$601)*Master!$R$5:$R$601+(Master!$R$5:$R$601>=Master!$Y$5:$Y$601)*Master!$Y$5:$Y$601) | E10: =SUMPRODUCT((Master!$Y$5:$Y$601>Master!$R$5:$R$601)*(Master!$Y$5:$Y$601-Master!$R$5:$R$601)) | F10: =SUM(Master!$Y$5:$Y$601) | G10: =SUMPRODUCT((Master!$R$5:$R$601>Master!$Y$5:$Y$601)*(Master!$J$5:$J$601>=(Master!$R$5:$R$601-Master!$Y$5:$Y$601))*(Master!$R$5:$R$601-Master!$Y$5:$Y$601)) | H10: =SUMPRODUCT((Master!$R$5:$R$601>Master!$Y$5:$Y$601)*(Master!$J$5:$J$601<(Master!$R$5:$R$601-Master!$Y$5:$Y$601))*(Master!$R$5:$R$601-Master!$Y$5:$Y$601-Master!$J$5:$J$601)) | I10: =IFERROR(D10/C10,0) | J10: =IFERROR((D10+G10)/C10,0) | K10: =SUMPRODUCT((Master!$R$5:$R$601>Master!$Y$5:$Y$601)*(Master!$J$5:$J$601<(Master!$R$5:$R$601-Master!$Y$5:$Y$601))*(Master!$R$5:$R$601-Master!$Y$5:$Y$601-Master!$J$5:$J$601)*Master!$K$5:$K$601) | L10: =SUMPRODUCT((Master!$R$5:$R$601>Master!$Y$5:$Y$601)*(Master!$J$5:$J$601>=(Master!$R$5:$R$601-Master!$Y$5:$Y$601))*(Master!$R$5:$R$601-Master!$Y$5:$Y$601)*Master!$K$5:$K$601) | M10: =SUMPRODUCT(Master!$Y$5:$Y$601*Master!$K$5:$K$601) | N10: =SUMPRODUCT(Master!$R$5:$R$601*Master!$K$5:$K$601) | O10: =SUMPRODUCT((Master!$R$5:$R$601>0)*(Master!$D$5:$D$601="B3")*(Master!$B$5:$B$601="To Buy"))
A11: Total | C11: =SUM(C5:C10) | D11: =SUM(D5:D10) | E11: =SUM(E5:E10) | F11: =SUM(F5:F10) | G11: =SUM(G5:G10) | H11: =SUM(H5:H10) | I11: =IFERROR(D11/C11,0) | J11: =IFERROR((D11+G11)/C11,0) | K11: =SUM(K5:K10) | L11: =SUM(L5:L10) | M11: =SUM(M5:M10) | N11: =SUM(N5:N10) | O11: =SUM(O5:O10)
A13: Role coverage — copies in each deck box that carry a target (Primary Purpose, column AE). "Min" is a sane Commander baseline; red = below min.
A14: Role | B14: Min | C14: D1 Quintorius Kand | D14: D2 Chulane | E14: D3 Atraxa | F14: D4 Betor | G14: D5 Shadrix | H14: D6 Purphoros | I14: Purposes counted
A15: Lands | B15: 36 | C15: =SUMPRODUCT((((Master!$AF$5:$AF$601="Land")+(Master!$AF$5:$AF$601="Flexible Fixing"))>0)*((Master!$M$5:$M$601<Master!$T$5:$T$601)*Master!$M$5:$M$601+(Master!$M$5:$M$601>=Master!$T$5:$T$601)*Master!$T$5:$T$601)) | D15: =SUMPRODUCT((((Master!$AF$5:$AF$601="Land")+(Master!$AF$5:$AF$601="Flexible Fixing"))>0)*((Master!$N$5:$N$601<Master!$U$5:$U$601)*Master!$N$5:$N$601+(Master!$N$5:$N$601>=Master!$U$5:$U$601)*Master!$U$5:$U$601)) | E15: =SUMPRODUCT((((Master!$AF$5:$AF$601="Land")+(Master!$AF$5:$AF$601="Flexible Fixing"))>0)*((Master!$O$5:$O$601<Master!$V$5:$V$601)*Master!$O$5:$O$601+(Master!$O$5:$O$601>=Master!$V$5:$V$601)*Master!$V$5:$V$601)) | F15: =SUMPRODUCT((((Master!$AF$5:$AF$601="Land")+(Master!$AF$5:$AF$601="Flexible Fixing"))>0)*((Master!$P$5:$P$601<Master!$W$5:$W$601)*Master!$P$5:$P$601+(Master!$P$5:$P$601>=Master!$W$5:$W$601)*Master!$W$5:$W$601)) | G15: =SUMPRODUCT((((Master!$AF$5:$AF$601="Land")+(Master!$AF$5:$AF$601="Flexible Fixing"))>0)*((Master!$Q$5:$Q$601<Master!$X$5:$X$601)*Master!$Q$5:$Q$601+(Master!$Q$5:$Q$601>=Master!$X$5:$X$601)*Master!$X$5:$X$601)) | H15: =SUMPRODUCT((((Master!$AF$5:$AF$601="Land")+(Master!$AF$5:$AF$601="Flexible Fixing"))>0)*((Master!$R$5:$R$601<Master!$Y$5:$Y$601)*Master!$R$5:$R$601+(Master!$R$5:$R$601>=Master!$Y$5:$Y$601)*Master!$Y$5:$Y$601)) | I15: Land, Flexible Fixing
A16: Ramp | B16: 10 | C16: =SUMPRODUCT((((Master!$AF$5:$AF$601="Ramp")+(Master!$AF$5:$AF$601="Mana Rock")+(Master!$AF$5:$AF$601="Defender Ramp")+(Master!$AF$5:$AF$601="Cost Reducer"))>0)*((Master!$M$5:$M$601<Master!$T$5:$T$601)*Master!$M$5:$M$601+(Master!$M$5:$M$601>=Master!$T$5:$T$601)*Master!$T$5:$T$601)) | D16: =SUMPRODUCT((((Master!$AF$5:$AF$601="Ramp")+(Master!$AF$5:$AF$601="Mana Rock")+(Master!$AF$5:$AF$601="Defender Ramp")+(Master!$AF$5:$AF$601="Cost Reducer"))>0)*((Master!$N$5:$N$601<Master!$U$5:$U$601)*Master!$N$5:$N$601+(Master!$N$5:$N$601>=Master!$U$5:$U$601)*Master!$U$5:$U$601)) | E16: =SUMPRODUCT((((Master!$AF$5:$AF$601="Ramp")+(Master!$AF$5:$AF$601="Mana Rock")+(Master!$AF$5:$AF$601="Defender Ramp")+(Master!$AF$5:$AF$601="Cost Reducer"))>0)*((Master!$O$5:$O$601<Master!$V$5:$V$601)*Master!$O$5:$O$601+(Master!$O$5:$O$601>=Master!$V$5:$V$601)*Master!$V$5:$V$601)) | F16: =SUMPRODUCT((((Master!$AF$5:$AF$601="Ramp")+(Master!$AF$5:$AF$601="Mana Rock")+(Master!$AF$5:$AF$601="Defender Ramp")+(Master!$AF$5:$AF$601="Cost Reducer"))>0)*((Master!$P$5:$P$601<Master!$W$5:$W$601)*Master!$P$5:$P$601+(Master!$P$5:$P$601>=Master!$W$5:$W$601)*Master!$W$5:$W$601)) | G16: =SUMPRODUCT((((Master!$AF$5:$AF$601="Ramp")+(Master!$AF$5:$AF$601="Mana Rock")+(Master!$AF$5:$AF$601="Defender Ramp")+(Master!$AF$5:$AF$601="Cost Reducer"))>0)*((Master!$Q$5:$Q$601<Master!$X$5:$X$601)*Master!$Q$5:$Q$601+(Master!$Q$5:$Q$601>=Master!$X$5:$X$601)*Master!$X$5:$X$601)) | H16: =SUMPRODUCT((((Master!$AF$5:$AF$601="Ramp")+(Master!$AF$5:$AF$601="Mana Rock")+(Master!$AF$5:$AF$601="Defender Ramp")+(Master!$AF$5:$AF$601="Cost Reducer"))>0)*((Master!$R$5:$R$601<Master!$Y$5:$Y$601)*Master!$R$5:$R$601+(Master!$R$5:$R$601>=Master!$Y$5:$Y$601)*Master!$Y$5:$Y$601)) | I16: Ramp, Mana Rock, Defender Ramp, Cost Reducer
A17: Card draw / advantage | B17: 10 | C17: =SUMPRODUCT((((Master!$AF$5:$AF$601="Card Draw")+(Master!$AF$5:$AF$601="Card Advantage")+(Master!$AF$5:$AF$601="Card Selection")+(Master!$AF$5:$AF$601="Value Engine")+(Master!$AF$5:$AF$601="Discard/Looting")+(Master!$AF$5:$AF$601="Wheel"))>0)*((Master!$M$5:$M$601<Master!$T$5:$T$601)*Master!$M$5:$M$601+(Master!$M$5:$M$601>=Master!$T$5:$T$601)*Master!$T$5:$T$601)) | D17: =SUMPRODUCT((((Master!$AF$5:$AF$601="Card Draw")+(Master!$AF$5:$AF$601="Card Advantage")+(Master!$AF$5:$AF$601="Card Selection")+(Master!$AF$5:$AF$601="Value Engine")+(Master!$AF$5:$AF$601="Discard/Looting")+(Master!$AF$5:$AF$601="Wheel"))>0)*((Master!$N$5:$N$601<Master!$U$5:$U$601)*Master!$N$5:$N$601+(Master!$N$5:$N$601>=Master!$U$5:$U$601)*Master!$U$5:$U$601)) | E17: =SUMPRODUCT((((Master!$AF$5:$AF$601="Card Draw")+(Master!$AF$5:$AF$601="Card Advantage")+(Master!$AF$5:$AF$601="Card Selection")+(Master!$AF$5:$AF$601="Value Engine")+(Master!$AF$5:$AF$601="Discard/Looting")+(Master!$AF$5:$AF$601="Wheel"))>0)*((Master!$O$5:$O$601<Master!$V$5:$V$601)*Master!$O$5:$O$601+(Master!$O$5:$O$601>=Master!$V$5:$V$601)*Master!$V$5:$V$601)) | F17: =SUMPRODUCT((((Master!$AF$5:$AF$601="Card Draw")+(Master!$AF$5:$AF$601="Card Advantage")+(Master!$AF$5:$AF$601="Card Selection")+(Master!$AF$5:$AF$601="Value Engine")+(Master!$AF$5:$AF$601="Discard/Looting")+(Master!$AF$5:$AF$601="Wheel"))>0)*((Master!$P$5:$P$601<Master!$W$5:$W$601)*Master!$P$5:$P$601+(Master!$P$5:$P$601>=Master!$W$5:$W$601)*Master!$W$5:$W$601)) | G17: =SUMPRODUCT((((Master!$AF$5:$AF$601="Card Draw")+(Master!$AF$5:$AF$601="Card Advantage")+(Master!$AF$5:$AF$601="Card Selection")+(Master!$AF$5:$AF$601="Value Engine")+(Master!$AF$5:$AF$601="Discard/Looting")+(Master!$AF$5:$AF$601="Wheel"))>0)*((Master!$Q$5:$Q$601<Master!$X$5:$X$601)*Master!$Q$5:$Q$601+(Master!$Q$5:$Q$601>=Master!$X$5:$X$601)*Master!$X$5:$X$601)) | H17: =SUMPRODUCT((((Master!$AF$5:$AF$601="Card Draw")+(Master!$AF$5:$AF$601="Card Advantage")+(Master!$AF$5:$AF$601="Card Selection")+(Master!$AF$5:$AF$601="Value Engine")+(Master!$AF$5:$AF$601="Discard/Looting")+(Master!$AF$5:$AF$601="Wheel"))>0)*((Master!$R$5:$R$601<Master!$Y$5:$Y$601)*Master!$R$5:$R$601+(Master!$R$5:$R$601>=Master!$Y$5:$Y$601)*Master!$Y$5:$Y$601)) | I17: Card Draw, Card Advantage, Card Selection, Value Engine, Discard/Looting, Wheel
A18: Removal / interaction | B18: 8 | C18: =SUMPRODUCT((((Master!$AF$5:$AF$601="Removal")+(Master!$AF$5:$AF$601="Artifact/Enchantment Removal")+(Master!$AF$5:$AF$601="Interaction")+(Master!$AF$5:$AF$601="Burn")+(Master!$AF$5:$AF$601="Graveyard Hate")+(Master!$AF$5:$AF$601="Stax/Tax"))>0)*((Master!$M$5:$M$601<Master!$T$5:$T$601)*Master!$M$5:$M$601+(Master!$M$5:$M$601>=Master!$T$5:$T$601)*Master!$T$5:$T$601)) | D18: =SUMPRODUCT((((Master!$AF$5:$AF$601="Removal")+(Master!$AF$5:$AF$601="Artifact/Enchantment Removal")+(Master!$AF$5:$AF$601="Interaction")+(Master!$AF$5:$AF$601="Burn")+(Master!$AF$5:$AF$601="Graveyard Hate")+(Master!$AF$5:$AF$601="Stax/Tax"))>0)*((Master!$N$5:$N$601<Master!$U$5:$U$601)*Master!$N$5:$N$601+(Master!$N$5:$N$601>=Master!$U$5:$U$601)*Master!$U$5:$U$601)) | E18: =SUMPRODUCT((((Master!$AF$5:$AF$601="Removal")+(Master!$AF$5:$AF$601="Artifact/Enchantment Removal")+(Master!$AF$5:$AF$601="Interaction")+(Master!$AF$5:$AF$601="Burn")+(Master!$AF$5:$AF$601="Graveyard Hate")+(Master!$AF$5:$AF$601="Stax/Tax"))>0)*((Master!$O$5:$O$601<Master!$V$5:$V$601)*Master!$O$5:$O$601+(Master!$O$5:$O$601>=Master!$V$5:$V$601)*Master!$V$5:$V$601)) | F18: =SUMPRODUCT((((Master!$AF$5:$AF$601="Removal")+(Master!$AF$5:$AF$601="Artifact/Enchantment Removal")+(Master!$AF$5:$AF$601="Interaction")+(Master!$AF$5:$AF$601="Burn")+(Master!$AF$5:$AF$601="Graveyard Hate")+(Master!$AF$5:$AF$601="Stax/Tax"))>0)*((Master!$P$5:$P$601<Master!$W$5:$W$601)*Master!$P$5:$P$601+(Master!$P$5:$P$601>=Master!$W$5:$W$601)*Master!$W$5:$W$601)) | G18: =SUMPRODUCT((((Master!$AF$5:$AF$601="Removal")+(Master!$AF$5:$AF$601="Artifact/Enchantment Removal")+(Master!$AF$5:$AF$601="Interaction")+(Master!$AF$5:$AF$601="Burn")+(Master!$AF$5:$AF$601="Graveyard Hate")+(Master!$AF$5:$AF$601="Stax/Tax"))>0)*((Master!$Q$5:$Q$601<Master!$X$5:$X$601)*Master!$Q$5:$Q$601+(Master!$Q$5:$Q$601>=Master!$X$5:$X$601)*Master!$X$5:$X$601)) | H18: =SUMPRODUCT((((Master!$AF$5:$AF$601="Removal")+(Master!$AF$5:$AF$601="Artifact/Enchantment Removal")+(Master!$AF$5:$AF$601="Interaction")+(Master!$AF$5:$AF$601="Burn")+(Master!$AF$5:$AF$601="Graveyard Hate")+(Master!$AF$5:$AF$601="Stax/Tax"))>0)*((Master!$R$5:$R$601<Master!$Y$5:$Y$601)*Master!$R$5:$R$601+(Master!$R$5:$R$601>=Master!$Y$5:$Y$601)*Master!$Y$5:$Y$601)) | I18: Removal, Artifact/Enchantment Removal, Interaction, Burn, Graveyard Hate, Stax/Tax
A19: Board wipes | B19: 2 | C19: =SUMPRODUCT((((Master!$AF$5:$AF$601="Board Wipe"))>0)*((Master!$M$5:$M$601<Master!$T$5:$T$601)*Master!$M$5:$M$601+(Master!$M$5:$M$601>=Master!$T$5:$T$601)*Master!$T$5:$T$601)) | D19: =SUMPRODUCT((((Master!$AF$5:$AF$601="Board Wipe"))>0)*((Master!$N$5:$N$601<Master!$U$5:$U$601)*Master!$N$5:$N$601+(Master!$N$5:$N$601>=Master!$U$5:$U$601)*Master!$U$5:$U$601)) | E19: =SUMPRODUCT((((Master!$AF$5:$AF$601="Board Wipe"))>0)*((Master!$O$5:$O$601<Master!$V$5:$V$601)*Master!$O$5:$O$601+(Master!$O$5:$O$601>=Master!$V$5:$V$601)*Master!$V$5:$V$601)) | F19: =SUMPRODUCT((((Master!$AF$5:$AF$601="Board Wipe"))>0)*((Master!$P$5:$P$601<Master!$W$5:$W$601)*Master!$P$5:$P$601+(Master!$P$5:$P$601>=Master!$W$5:$W$601)*Master!$W$5:$W$601)) | G19: =SUMPRODUCT((((Master!$AF$5:$AF$601="Board Wipe"))>0)*((Master!$Q$5:$Q$601<Master!$X$5:$X$601)*Master!$Q$5:$Q$601+(Master!$Q$5:$Q$601>=Master!$X$5:$X$601)*Master!$X$5:$X$601)) | H19: =SUMPRODUCT((((Master!$AF$5:$AF$601="Board Wipe"))>0)*((Master!$R$5:$R$601<Master!$Y$5:$Y$601)*Master!$R$5:$R$601+(Master!$R$5:$R$601>=Master!$Y$5:$Y$601)*Master!$Y$5:$Y$601)) | I19: Board Wipe
A20: Protection | B20: 3 | C20: =SUMPRODUCT((((Master!$AF$5:$AF$601="Protection"))>0)*((Master!$M$5:$M$601<Master!$T$5:$T$601)*Master!$M$5:$M$601+(Master!$M$5:$M$601>=Master!$T$5:$T$601)*Master!$T$5:$T$601)) | D20: =SUMPRODUCT((((Master!$AF$5:$AF$601="Protection"))>0)*((Master!$N$5:$N$601<Master!$U$5:$U$601)*Master!$N$5:$N$601+(Master!$N$5:$N$601>=Master!$U$5:$U$601)*Master!$U$5:$U$601)) | E20: =SUMPRODUCT((((Master!$AF$5:$AF$601="Protection"))>0)*((Master!$O$5:$O$601<Master!$V$5:$V$601)*Master!$O$5:$O$601+(Master!$O$5:$O$601>=Master!$V$5:$V$601)*Master!$V$5:$V$601)) | F20: =SUMPRODUCT((((Master!$AF$5:$AF$601="Protection"))>0)*((Master!$P$5:$P$601<Master!$W$5:$W$601)*Master!$P$5:$P$601+(Master!$P$5:$P$601>=Master!$W$5:$W$601)*Master!$W$5:$W$601)) | G20: =SUMPRODUCT((((Master!$AF$5:$AF$601="Protection"))>0)*((Master!$Q$5:$Q$601<Master!$X$5:$X$601)*Master!$Q$5:$Q$601+(Master!$Q$5:$Q$601>=Master!$X$5:$X$601)*Master!$X$5:$X$601)) | H20: =SUMPRODUCT((((Master!$AF$5:$AF$601="Protection"))>0)*((Master!$R$5:$R$601<Master!$Y$5:$Y$601)*Master!$R$5:$R$601+(Master!$R$5:$R$601>=Master!$Y$5:$Y$601)*Master!$Y$5:$Y$601)) | I20: Protection
A21: Recursion / reanimation | B21: 3 | C21: =SUMPRODUCT((((Master!$AF$5:$AF$601="Recursion")+(Master!$AF$5:$AF$601="Reanimation"))>0)*((Master!$M$5:$M$601<Master!$T$5:$T$601)*Master!$M$5:$M$601+(Master!$M$5:$M$601>=Master!$T$5:$T$601)*Master!$T$5:$T$601)) | D21: =SUMPRODUCT((((Master!$AF$5:$AF$601="Recursion")+(Master!$AF$5:$AF$601="Reanimation"))>0)*((Master!$N$5:$N$601<Master!$U$5:$U$601)*Master!$N$5:$N$601+(Master!$N$5:$N$601>=Master!$U$5:$U$601)*Master!$U$5:$U$601)) | E21: =SUMPRODUCT((((Master!$AF$5:$AF$601="Recursion")+(Master!$AF$5:$AF$601="Reanimation"))>0)*((Master!$O$5:$O$601<Master!$V$5:$V$601)*Master!$O$5:$O$601+(Master!$O$5:$O$601>=Master!$V$5:$V$601)*Master!$V$5:$V$601)) | F21: =SUMPRODUCT((((Master!$AF$5:$AF$601="Recursion")+(Master!$AF$5:$AF$601="Reanimation"))>0)*((Master!$P$5:$P$601<Master!$W$5:$W$601)*Master!$P$5:$P$601+(Master!$P$5:$P$601>=Master!$W$5:$W$601)*Master!$W$5:$W$601)) | G21: =SUMPRODUCT((((Master!$AF$5:$AF$601="Recursion")+(Master!$AF$5:$AF$601="Reanimation"))>0)*((Master!$Q$5:$Q$601<Master!$X$5:$X$601)*Master!$Q$5:$Q$601+(Master!$Q$5:$Q$601>=Master!$X$5:$X$601)*Master!$X$5:$X$601)) | H21: =SUMPRODUCT((((Master!$AF$5:$AF$601="Recursion")+(Master!$AF$5:$AF$601="Reanimation"))>0)*((Master!$R$5:$R$601<Master!$Y$5:$Y$601)*Master!$R$5:$R$601+(Master!$R$5:$R$601>=Master!$Y$5:$Y$601)*Master!$Y$5:$Y$601)) | I21: Recursion, Reanimation
A22: Win / payoff | B22: 0 | C22: =SUMPRODUCT((((Master!$AF$5:$AF$601="Finisher")+(Master!$AF$5:$AF$601="Drain Payoff")+(Master!$AF$5:$AF$601="Toughness Payoff")+(Master!$AF$5:$AF$601="Counters Payoff")+(Master!$AF$5:$AF$601="Proliferate")+(Master!$AF$5:$AF$601="Aristocrats Payoff")+(Master!$AF$5:$AF$601="Lord/Anthem")+(Master!$AF$5:$AF$601="Token Producer")+(Master!$AF$5:$AF$601="Sacrifice Outlet")+(Master!$AF$5:$AF$601="Haste Enabler")+(Master!$AF$5:$AF$601="Blink")+(Master!$AF$5:$AF$601="Lifegain")+(Master!$AF$5:$AF$601="Combat Trick")+(Master!$AF$5:$AF$601="Evasion")+(Master!$AF$5:$AF$601="Copy/Clone")+(Master!$AF$5:$AF$601="Mana Sink")+(Master!$AF$5:$AF$601="Tutor")+(Master!$AF$5:$AF$601="Utility Creature"))>0)*((Master!$M$5:$M$601<Master!$T$5:$T$601)*Master!$M$5:$M$601+(Master!$M$5:$M$601>=Master!$T$5:$T$601)*Master!$T$5:$T$601)) | D22: =SUMPRODUCT((((Master!$AF$5:$AF$601="Finisher")+(Master!$AF$5:$AF$601="Drain Payoff")+(Master!$AF$5:$AF$601="Toughness Payoff")+(Master!$AF$5:$AF$601="Counters Payoff")+(Master!$AF$5:$AF$601="Proliferate")+(Master!$AF$5:$AF$601="Aristocrats Payoff")+(Master!$AF$5:$AF$601="Lord/Anthem")+(Master!$AF$5:$AF$601="Token Producer")+(Master!$AF$5:$AF$601="Sacrifice Outlet")+(Master!$AF$5:$AF$601="Haste Enabler")+(Master!$AF$5:$AF$601="Blink")+(Master!$AF$5:$AF$601="Lifegain")+(Master!$AF$5:$AF$601="Combat Trick")+(Master!$AF$5:$AF$601="Evasion")+(Master!$AF$5:$AF$601="Copy/Clone")+(Master!$AF$5:$AF$601="Mana Sink")+(Master!$AF$5:$AF$601="Tutor")+(Master!$AF$5:$AF$601="Utility Creature"))>0)*((Master!$N$5:$N$601<Master!$U$5:$U$601)*Master!$N$5:$N$601+(Master!$N$5:$N$601>=Master!$U$5:$U$601)*Master!$U$5:$U$601)) | E22: =SUMPRODUCT((((Master!$AF$5:$AF$601="Finisher")+(Master!$AF$5:$AF$601="Drain Payoff")+(Master!$AF$5:$AF$601="Toughness Payoff")+(Master!$AF$5:$AF$601="Counters Payoff")+(Master!$AF$5:$AF$601="Proliferate")+(Master!$AF$5:$AF$601="Aristocrats Payoff")+(Master!$AF$5:$AF$601="Lord/Anthem")+(Master!$AF$5:$AF$601="Token Producer")+(Master!$AF$5:$AF$601="Sacrifice Outlet")+(Master!$AF$5:$AF$601="Haste Enabler")+(Master!$AF$5:$AF$601="Blink")+(Master!$AF$5:$AF$601="Lifegain")+(Master!$AF$5:$AF$601="Combat Trick")+(Master!$AF$5:$AF$601="Evasion")+(Master!$AF$5:$AF$601="Copy/Clone")+(Master!$AF$5:$AF$601="Mana Sink")+(Master!$AF$5:$AF$601="Tutor")+(Master!$AF$5:$AF$601="Utility Creature"))>0)*((Master!$O$5:$O$601<Master!$V$5:$V$601)*Master!$O$5:$O$601+(Master!$O$5:$O$601>=Master!$V$5:$V$601)*Master!$V$5:$V$601)) | F22: =SUMPRODUCT((((Master!$AF$5:$AF$601="Finisher")+(Master!$AF$5:$AF$601="Drain Payoff")+(Master!$AF$5:$AF$601="Toughness Payoff")+(Master!$AF$5:$AF$601="Counters Payoff")+(Master!$AF$5:$AF$601="Proliferate")+(Master!$AF$5:$AF$601="Aristocrats Payoff")+(Master!$AF$5:$AF$601="Lord/Anthem")+(Master!$AF$5:$AF$601="Token Producer")+(Master!$AF$5:$AF$601="Sacrifice Outlet")+(Master!$AF$5:$AF$601="Haste Enabler")+(Master!$AF$5:$AF$601="Blink")+(Master!$AF$5:$AF$601="Lifegain")+(Master!$AF$5:$AF$601="Combat Trick")+(Master!$AF$5:$AF$601="Evasion")+(Master!$AF$5:$AF$601="Copy/Clone")+(Master!$AF$5:$AF$601="Mana Sink")+(Master!$AF$5:$AF$601="Tutor")+(Master!$AF$5:$AF$601="Utility Creature"))>0)*((Master!$P$5:$P$601<Master!$W$5:$W$601)*Master!$P$5:$P$601+(Master!$P$5:$P$601>=Master!$W$5:$W$601)*Master!$W$5:$W$601)) | G22: =SUMPRODUCT((((Master!$AF$5:$AF$601="Finisher")+(Master!$AF$5:$AF$601="Drain Payoff")+(Master!$AF$5:$AF$601="Toughness Payoff")+(Master!$AF$5:$AF$601="Counters Payoff")+(Master!$AF$5:$AF$601="Proliferate")+(Master!$AF$5:$AF$601="Aristocrats Payoff")+(Master!$AF$5:$AF$601="Lord/Anthem")+(Master!$AF$5:$AF$601="Token Producer")+(Master!$AF$5:$AF$601="Sacrifice Outlet")+(Master!$AF$5:$AF$601="Haste Enabler")+(Master!$AF$5:$AF$601="Blink")+(Master!$AF$5:$AF$601="Lifegain")+(Master!$AF$5:$AF$601="Combat Trick")+(Master!$AF$5:$AF$601="Evasion")+(Master!$AF$5:$AF$601="Copy/Clone")+(Master!$AF$5:$AF$601="Mana Sink")+(Master!$AF$5:$AF$601="Tutor")+(Master!$AF$5:$AF$601="Utility Creature"))>0)*((Master!$Q$5:$Q$601<Master!$X$5:$X$601)*Master!$Q$5:$Q$601+(Master!$Q$5:$Q$601>=Master!$X$5:$X$601)*Master!$X$5:$X$601)) | H22: =SUMPRODUCT((((Master!$AF$5:$AF$601="Finisher")+(Master!$AF$5:$AF$601="Drain Payoff")+(Master!$AF$5:$AF$601="Toughness Payoff")+(Master!$AF$5:$AF$601="Counters Payoff")+(Master!$AF$5:$AF$601="Proliferate")+(Master!$AF$5:$AF$601="Aristocrats Payoff")+(Master!$AF$5:$AF$601="Lord/Anthem")+(Master!$AF$5:$AF$601="Token Producer")+(Master!$AF$5:$AF$601="Sacrifice Outlet")+(Master!$AF$5:$AF$601="Haste Enabler")+(Master!$AF$5:$AF$601="Blink")+(Master!$AF$5:$AF$601="Lifegain")+(Master!$AF$5:$AF$601="Combat Trick")+(Master!$AF$5:$AF$601="Evasion")+(Master!$AF$5:$AF$601="Copy/Clone")+(Master!$AF$5:$AF$601="Mana Sink")+(Master!$AF$5:$AF$601="Tutor")+(Master!$AF$5:$AF$601="Utility Creature"))>0)*((Master!$R$5:$R$601<Master!$Y$5:$Y$601)*Master!$R$5:$R$601+(Master!$R$5:$R$601>=Master!$Y$5:$Y$601)*Master!$Y$5:$Y$601)) | I22: Finisher, Drain Payoff, Toughness Payoff, Counters Payoff, Proliferate, Aristocrats Payoff, Lord/Anthem, Token Producer, Sacrifice Outlet, Haste Enabler, Blink, Lifegain, Combat Trick, Evasion, Copy/Clone, Mana Sink, Tutor, Utility Creature
A24: Inventory and status
A25: Status | B25: Rows | C25: Meaning
A26: In Hand | B26: =COUNTIF(Master!$B$5:$B$601,"In Hand") | C26: Targeted and owned in full
A27: Ordered | B27: =COUNTIF(Master!$B$5:$B$601,"Ordered") | C27: Short copies are on order (I >= shortfall)
A28: To Buy | B28: =COUNTIF(Master!$B$5:$B$601,"To Buy") | C28: Targeted, not owned, not ordered
A29: Bench | B29: =COUNTIF(Master!$B$5:$B$601,"Bench") | C29: Owned, no target, sitting in the bench box
A30: Bench-Sub | B30: =COUNTIF(Master!$B$5:$B$601,"Bench-Sub") | C30: Owned, no target, sitting in a deck box as a placeholder
A31: Extra | B31: =COUNTIF(Master!$B$5:$B$601,"Extra") | C31: Owned more copies than targeted
A32: Extra-Sub | B32: =COUNTIF(Master!$B$5:$B$601,"Extra-Sub") | C32: Extra copy sitting in a deck box as a placeholder
A33: B3 Option | B33: =COUNTIF(Master!$B$5:$B$601,"B3 Option") | C33: Max-tier candidate, not targeted or owned
A34: Remove | B34: =COUNTIF(Master!$B$5:$B$601,"Remove") | C34: No target, not owned — superseded row, safe to delete
A36: Money
A37: Cards owned (all copies) | B37: =SUM(Master!$F$5:$F$601)
A38: Bench copies (B-A) | B38: =SUM(Master!$Z$5:$Z$601)
A39: Bench market value | B39: =SUMPRODUCT(Master!$Z$5:$Z$601*Master!$K$5:$K$601)
A40: Copies on order | B40: =SUM(Master!$J$5:$J$601)
A41: Value of copies on order | B41: =SUMPRODUCT(Master!$J$5:$J$601*Master!$K$5:$K$601)
A42: $ To Buy, all decks (Master K) | B42: =SUM(Master!$L$5:$L$601)
A43: Value of all six target builds | B43: =SUM(N5:N10)
...

Sheet Master
T1: 4 | U1: 13 | V1: 12 | W1: 37 | X1: 42 | Y1: 59
M2: =SUM(M$5:M$601) | N2: =SUM(N$5:N$601) | O2: =SUM(O$5:O$601) | P2: =SUM(P$5:P$601) | Q2: =SUM(Q$5:Q$601) | R2: =SUM(R$5:R$601) | T2: =SUM(T$5:T$601) | U2: =SUM(U$5:U$601) | V2: =SUM(V$5:V$601) | W2: =SUM(W$5:W$601) | X2: =SUM(X$5:X$601) | Y2: =SUM(Y$5:Y$601)
F3: =SUM(F5:F601) | J3: =SUM(J5:J601) | K3: =SUM(K5:K83) | M3: Target | R3: Bnch | S3: =SUM(S5:S601) | T3: Actual | Y3: Bnch | Z3: =SUM(Z5:Z601)
A4: Card | B4: Status | C4: My To Buy List | D4: Bracket | E4: Qty | F4: Own | G4: Extra (Bench) | H4: Buy Count | I4: In Cart | J4: Ordered | K4: $ Each | L4: $ To Buy | M4: D1-T | N4: D2-T | O4: D3-T | P4: D4-T | Q4: D5-T | R4: D6-T | S4: B-T | T4: D1-A | U4: D2-A | V4: D3-A | W4: D4-A | X4: D5-A | Y4: D6-A | Z4: B-A | AA4: Type | AB4: Sub-Type | AC4: Color | AD4: MV | AE4: Series | AF4: Primary Purpose | AG4: Primary Mechanic | AH4: Secondary Mechanic | AI4: Tertiary Mechanic | AJ4: Notes | AK4: Moves
A5: Elas il-Kor, Sadistic Pilgrim | B5: =IF(AND(F5<>0,E5=F5),"In Hand",IF(AND(E5<>0,E5<F5,SUM(M5:R5)=0,SUM(T5:Y5)>0),"Extra-Sub",IF(AND(E5=0,E5<F5,SUM(M5:R5)=0,SUM(T5:Y5)>0),"Bench-Sub",IF(AND(E5=0,F5>0),"Bench",IF(E5<F5,"Extra",IF(AND(J5="",E5>F5),"To Buy",IF(SUM(J5,F5)<E5,"To Buy",IF(AND(SUM(J5,F5)>=E5,J5<>""),"Ordered",IF(AND(E5=0,F5=0,D5="B3"),"B3 Option",IF(AND(E5=0,F5=0),"Remove","To Buy")))))))))) | C5: 1 | D5: B2 | E5: =SUM(M5:S5) | F5: =SUM(T5:Z5) | G5: =IF((F5-E5)>=0,F5-E5,0) | H5: =MAX(0,$E5-$F5-$J5) | K5: 3.11 | L5: =IF(AND($H5>0,ISNUMBER($K5)),$H5*$K5,0) | Q5: 1 | S5: =IF(AND(J5<>"",SUM(M5:R5)=0),J5,"") | AA5: Legendary Creature | AB5: Phyrexian Kor Cleric | AC5: Multi | AD5: 2 | AE5: Dominaria United | AF5: Drain Payoff | AG5: Gains you 1 life whenever another creature you control enters | AH5: Each opponent loses 1 life whenever another creature you control dies | AI5: Deathtouch body
A6: Fervor | B6: =IF(AND(F6<>0,E6=F6),"In Hand",IF(AND(E6<>0,E6<F6,SUM(M6:R6)=0,SUM(T6:Y6)>0),"Extra-Sub",IF(AND(E6=0,E6<F6,SUM(M6:R6)=0,SUM(T6:Y6)>0),"Bench-Sub",IF(AND(E6=0,F6>0),"Bench",IF(E6<F6,"Extra",IF(AND(J6="",E6>F6),"To Buy",IF(SUM(J6,F6)<E6,"To Buy",IF(AND(SUM(J6,F6)>=E6,J6<>""),"Ordered",IF(AND(E6=0,F6=0,D6="B3"),"B3 Option",IF(AND(E6=0,F6=0),"Remove","To Buy")))))))))) | C6: 1 | D6: B3 | E6: =SUM(M6:S6) | F6: =SUM(T6:Z6) | G6: =IF((F6-E6)>=0,F6-E6,0) | H6: =MAX(0,$E6-$F6-$J6) | K6: 4.21 | L6: =IF(AND($H6>0,ISNUMBER($K6)),$H6*$K6,0) | R6: 1 | S6: =IF(AND(J6<>"",SUM(M6:R6)=0),J6,"") | AA6: Enchantment | AC6: R | AD6: 3 | AE6: Weatherlight | AF6: Tuned add | AG6: Creatures you control have haste. (They can attack and {T} as soon as they come under your control.) | AJ6: D6 Tuned add; targeted 2026-09-02; replaces Akoum Hellhound | AK6: [T] targeted D6 (Tuned add, replaces Akoum Hellhound); [A later] ->D6 when bought
A7: Kambal, Consul of Allocation | B7: =IF(AND(F7<>0,E7=F7),"In Hand",IF(AND(E7<>0,E7<F7,SUM(M7:R7)=0,SUM(T7:Y7)>0),"Extra-Sub",IF(AND(E7=0,E7<F7,SUM(M7:R7)=0,SUM(T7:Y7)>0),"Bench-Sub",IF(AND(E7=0,F7>0),"Bench",IF(E7<F7,"Extra",IF(AND(J7="",E7>F7),"To Buy",IF(SUM(J7,F7)<E7,"To Buy",IF(AND(SUM(J7,F7)>=E7,J7<>""),"Ordered",IF(AND(E7=0,F7=0,D7="B3"),"B3 Option",IF(AND(E7=0,F7=0),"Remove","To Buy")))))))))) | C7: 1 | D7: B3 | E7: =SUM(M7:S7) | F7: =SUM(T7:Z7) | G7: =IF((F7-E7)>=0,F7-E7,0) | H7: =MAX(0,$E7-$F7-$J7) | K7: 10.17 | L7: =IF(AND($H7>0,ISNUMBER($K7)),$H7*$K7,0) | Q7: 1 | S7: =IF(AND(J7<>"",SUM(M7:R7)=0),J7,"") | AA7: Legendary Creature | AB7: Human Advisor | AC7: BW | AD7: 3 | AE7: Kaladesh | AF7: Tuned add | AG7: Whenever an opponent casts a noncreature spell, that player loses 2 life and you gain 2 life. | AJ7: D5 Tuned add; targeted 2026-09-02; replaces Great Fierce Bee | AK7: [T] targeted D5 (Tuned add, replaces Great Fierce Bee); [A later] ->D5 when bought
A8: Mentor of the Meek | B8: =IF(AND(F8<>0,E8=F8),"In Hand",IF(AND(E8<>0,E8<F8,SUM(M8:R8)=0,SUM(T8:Y8)>0),"Extra-Sub",IF(AND(E8=0,E8<F8,SUM(M8:R8)=0,SUM(T8:Y8)>0),"Bench-Sub",IF(AND(E8=0,F8>0),"Bench",IF(E8<F8,"Extra",IF(AND(J8="",E8>F8),"To Buy",IF(SUM(J8,F8)<E8,"To Buy",IF(AND(SUM(J8,F8)>=E8,J8<>""),"Ordered",IF(AND(E8=0,F8=0,D8="B3"),"B3 Option",IF(AND(E8=0,F8=0),"Remove","To Buy")))))))))) | C8: 1 | D8: B3 | E8: =SUM(M8:S8) | F8: =SUM(T8:Z8) | G8: =IF((F8-E8)>=0,F8-E8,0) | H8: =MAX(0,$E8-$F8-$J8) | K8: 4.95 | L8: =IF(AND($H8>0,ISNUMBER($K8)),$H8*$K8,0) | Q8: 1 | S8: =IF(AND(J8<>"",SUM(M8:R8)=0),J8,"") | AA8: Creature | AB8: Human Soldier | AC8: W | AD8: 3 | AE8: Innistrad | AF8: Tuned add | AG8: Whenever another creature you control with power 2 or less enters, you may pay {1}. If you do, draw a card. | AJ8: D5 Tuned add; targeted 2026-09-02; replaces Hemlock Vial | AK8: [T] targeted D5 (Tuned add, replaces Hemlock Vial); [A later] ->D5 when bought
A9: Molten Echoes | B9: =IF(AND(F9<>0,E9=F9),"In Hand",IF(AND(E9<>0,E9<F9,SUM(M9:R9)=0,SUM(T9:Y9)>0),"Extra-Sub",IF(AND(E9=0,E9<F9,SUM(M9:R9)=0,SUM(T9:Y9)>0),"Bench-Sub",IF(AND(E9=0,F9>0),"Bench",IF(E9<F9,"Extra",IF(AND(J9="",E9>F9),"To Buy",IF(SUM(J9,F9)<E9,"To Buy",IF(AND(SUM(J9,F9)>=E9,J9<>""),"Ordered",IF(AND(E9=0,F9=0,D9="B3"),"B3 Option",IF(AND(E9=0,F9=0),"Remove","To Buy")))))))))) | C9: 1 | D9: B3 | E9: =SUM(M9:S9) | F9: =SUM(T9:Z9) | G9: =IF((F9-E9)>=0,F9-E9,0) | H9: =MAX(0,$E9-$F9-$J9) | K9: 9.51 | L9: =IF(AND($H9>0,ISNUMBER($K9)),$H9*$K9,0) | R9: 1 | S9: =IF(AND(J9<>"",SUM(M9:R9)=0),J9,"") | AA9: Enchantment | AC9: R | AD9: 4 | AE9: Commander 2020 | AF9: Tuned add | AG9: As this enchantment enters, choose a creature type. Whenever a nontoken creature you control of the chosen type enters, | AJ9: D6 Tuned add; targeted 2026-09-02; replaces Monastery Raid | AK9: [T] targeted D6 (Tuned add, replaces Monastery Raid); [A later] ->D6 when bought
A10: Night's Whisper | B10: =IF(AND(F10<>0,E10=F10),"In Hand",IF(AND(E10<>0,E10<F10,SUM(M10:R10)=0,SUM(T10:Y10)>0),"Extra-Sub",IF(AND(E10=0,E10<F10,SUM(M10:R10)=0,SUM(T10:Y10)>0),"Bench-Sub",IF(AND(E10=0,F10>0),"Bench",IF(E10<F10,"Extra",IF(AND(J10="",E10>F10),"To Buy",IF(SUM(J10,F10)<E10,"To Buy",IF(AND(SUM(J10,F10)>=E10,J10<>""),"Ordered",IF(AND(E10=0,F10=0,D10="B3"),"B3 Option",IF(AND(E10=0,F10=0),"Remove","To Buy")))))))))) | C10: 1 | D10: B3 | E10: =SUM(M10:S10) | F10: =SUM(T10:Z10) | G10: =IF((F10-E10)>=0,F10-E10,0) | H10: =MAX(0,$E10-$F10-$J10) | K10: 5.42 | L10: =IF(AND($H10>0,ISNUMBER($K10)),$H10*$K10,0) | Q10: 1 | S10: =IF(AND(J10<>"",SUM(M10:R10)=0),J10,"") | AA10: Sorcery | AC10: B | AD10: 2 | AE10: Fifth Dawn | AF10: Tuned add | AG10: You draw two cards and lose 2 life. | AJ10: D5 Tuned add; targeted 2026-09-02; replaces Lake-town Lookout; B3/Max add for D3; NOT targeted; replaces Troll Negotiations when bought | AK10: [T] targeted D5 (Tuned add, replaces Lake-town Lookout); [A later] ->D5 when bought; [B3/Max, not targeted] when bought ->D3, replaces Troll Negotiations (Troll Negotiations->B)
A11: Ophiomancer | B11: =IF(AND(F11<>0,E11=F11),"In Hand",IF(AND(E11<>0,E11<F11,SUM(M11:R11)=0,SUM(T11:Y11)>0),"Extra-Sub",IF(AND(E11=0,E11<F11,SUM(M11:R11)=0,SUM(T11:Y11)>0),"Bench-Sub",IF(AND(E11=0,F11>0),"Bench",IF(E11<F11,"Extra",IF(AND(J11="",E11>F11),"To Buy",IF(SUM(J11,F11)<E11,"To Buy",IF(AND(SUM(J11,F11)>=E11,J11<>""),"Ordered",IF(AND(E11=0,F11=0,D11="B3"),"B3 Option",IF(AND(E11=0,F11=0),"Remove","To Buy")))))))))) | C11: 1 | D11: B2 | E11: =SUM(M11:S11) | F11: =SUM(T11:Z11) | G11: =IF((F11-E11)>=0,F11-E11,0) | H11: =MAX(0,$E11-$F11-$J11) | K11: 0.96 | L11: =IF(AND($H11>0,ISNUMBER($K11)),$H11*$K11,0) | Q11: 1 | S11: =IF(AND(J11<>"",SUM(M11:R11)=0),J11,"") | AA11: Creature | AB11: Human Shaman | AC11: B | AD11: 3 | AE11: Commander 2013 | AF11: Token Producer | AG11: Each upkeep, creates a 1/1 deathtouch Snake token if you control none | AJ11: Removed from cart 2026-09-02: only sellers with 1-3 cards had it (shipping >30% of package)
A12: Ruby Medallion | B12: =IF(AND(F12<>0,E12=F12),"In Hand",IF(AND(E12<>0,E12<F12,SUM(M12:R12)=0,SUM(T12:Y12)>0),"Extra-Sub",IF(AND(E12=0,E12<F12,SUM(M12:R12)=0,SUM(T12:Y12)>0),"Bench-Sub",IF(AND(E12=0,F12>0),"Bench",IF(E12<F12,"Extra",IF(AND(J12="",E12>F12),"To Buy",IF(SUM(J12,F12)<E12,"To Buy",IF(AND(SUM(J12,F12)>=E12,J12<>""),"Ordered",IF(AND(E12=0,F12=0,D12="B3"),"B3 Option",IF(AND(E12=0,F12=0),"Remove","To Buy")))))))))) | C12: 1 | D12: B3 | E12: =SUM(M12:S12) | F12: =SUM(T12:Z12) | G12: =IF((F12-E12)>=0,F12-E12,0) | H12: =MAX(0,$E12-$F12-$J12) | K12: 14.81 | L12: =IF(AND($H12>0,ISNUMBER($K12)),$H12*$K12,0) | R12: 1 | S12: =IF(AND(J12<>"",SUM(M12:R12)=0),J12,"") | AA12: Artifact | AC12: C | AD12: 2 | AE12: Tempest | AF12: Tuned add | AG12: Red spells you cast cost {1} less to cast. | AJ12: D6 Tuned add; targeted 2026-09-02; replaces Dwarven Mauler | AK12: [T] targeted D6 (Tuned add, replaces Dwarven Mauler); [A later] ->D6 when bought
A13: Rundvelt Hordemaster | B13: =IF(AND(F13<>0,E13=F13),"In Hand",IF(AND(E13<>0,E13<F13,SUM(M13:R13)=0,SUM(T13:Y13)>0),"Extra-Sub",IF(AND(E13=0,E13<F13,SUM(M13:R13)=0,SUM(T13:Y13)>0),"Bench-Sub",IF(AND(E13=0,F13>0),"Bench",IF(E13<F13,"Extra",IF(AND(J13="",E13>F13),"To Buy",IF(SUM(J13,F13)<E13,"To Buy",IF(AND(SUM(J13,F13)>=E13,J13<>""),"Ordered",IF(AND(E13=0,F13=0,D13="B3"),"B3 Option",IF(AND(E13=0,F13=0),"Remove","To Buy")))))))))) | C13: 1 | D13: B3 | E13: =SUM(M13:S13) | F13: =SUM(T13:Z13) | G13: =IF((F13-E13)>=0,F13-E13,0) | H13: =MAX(0,$E13-$F13-$J13) | K13: 4.87 | L13: =IF(AND($H13>0,ISNUMBER($K13)),$H13*$K13,0) | R13: 1 | S13: =IF(AND(J13<>"",SUM(M13:R13)=0),J13,"") | AA13: Creature | AB13: Goblin Warrior | AC13: R | AD13: 2 | AE13: Dominaria United | AF13: Tuned add | AG13: Other Goblins you control get +1/+1. Whenever this creature or another Goblin you control dies, exile the top card of yo | AJ13: D6 Tuned add; targeted 2026-09-02; replaces Burning Curiosity | AK13: [T] targeted D6 (Tuned add, replaces Burning Curiosity); [A later] ->D6 when bought
A14: Skullclamp | B14: =IF(AND(F14<>0,E14=F14),"In Hand",IF(AND(E14<>0,E14<F14,SUM(M14:R14)=0,SUM(T14:Y14)>0),"Extra-Sub",IF(AND(E14=0,E14<F14,SUM(M14:R14)=0,SUM(T14:Y14)>0),"Bench-Sub",IF(AND(E14=0,F14>0),"Bench",IF(E14<F14,"Extra",IF(AND(J14="",E14>F14),"To Buy",IF(SUM(J14,F14)<E14,"To Buy",IF(AND(SUM(J14,F14)>=E14,J14<>""),"Ordered",IF(AND(E14=0,F14=0,D14="B3"),"B3 Option",IF(AND(E14=0,F14=0),"Remove","To Buy")))))))))) | C14: 1 | D14: B2 | E14: =SUM(M14:S14) | F14: =SUM(T14:Z14) | G14: =IF((F14-E14)>=0,F14-E14,0) | H14: =MAX(0,$E14-$F14-$J14) | K14: 5.89 | L14: =IF(AND($H14>0,ISNUMBER($K14)),$H14*$K14,0) | M14: 1 | Q14: 1 | S14: =IF(AND(J14<>"",SUM(M14:R14)=0),J14,"") | T14: 1 | AA14: Artifact | AB14: Equipment | AC14: C | AD14: 1 | AE14: Darksteel | AF14: Card Draw | AG14: Equipped creature gets +1/-1 | AH14: Draw two cards whenever equipped creature dies | AJ14: Tuned add (2nd copy); NOT a Game Changer per the official list; D5 Tuned add; targeted 2026-09-02; replaces Suture Priest | AK14: [T] targeted D5 (Tuned add, replaces Suture Priest); [A later] ->D5 when bought
A15: Teysa Karlov | B15: =IF(AND(F15<>0,E15=F15),"In Hand",IF(AND(E15<>0,E15<F15,SUM(M15:R15)=0,SUM(T15:Y15)>0),"Extra-Sub",IF(AND(E15=0,E15<F15,SUM(M15:R15)=0,SUM(T15:Y15)>0),"Bench-Sub",IF(AND(E15=0,F15>0),"Bench",IF(E15<F15,"Extra",IF(AND(J15="",E15>F15),"To Buy",IF(SUM(J15,F15)<E15,"To Buy",IF(AND(SUM(J15,F15)>=E15,J15<>""),"Ordered",IF(AND(E15=0,F15=0,D15="B3"),"B3 Option",IF(AND(E15=0,F15=0),"Remove","To Buy")))))))))) | C15: 1 | D15: B3 | E15: =SUM(M15:S15) | F15: =SUM(T15:Z15) | G15: =IF((F15-E15)>=0,F15-E15,0) | H15: =MAX(0,$E15-$F15-$J15) | K15: 2.67 | L15: =IF(AND($H15>0,ISNUMBER($K15)),$H15*$K15,0) | Q15: 1 | S15: =IF(AND(J15<>"",SUM(M15:R15)=0),J15,"") | AA15: Legendary Creature | AB15: Human Advisor | AC15: BW | AD15: 4 | AE15: Ravnica Allegiance | AF15: Tuned add | AG15: If a creature dying causes a triggered ability of a permanent you control to trigger, that ability triggers an additiona | AJ15: D5 Tuned add; targeted 2026-09-02; replaces Prideful Feastling | AK15: [T] targeted D5 (Tuned add, replaces Prideful Feastling); [A later] ->D5 when bought
A16: Tree of Perdition | B16: =IF(AND(F16<>0,E16=F16),"In Hand",IF(AND(E16<>0,E16<F16,SUM(M16:R16)=0,SUM(T16:Y16)>0),"Extra-Sub",IF(AND(E16=0,E16<F16,SUM(M16:R16)=0,SUM(T16:Y16)>0),"Bench-Sub",IF(AND(E16=0,F16>0),"Bench",IF(E16<F16,"Extra",IF(AND(J16="",E16>F16),"To Buy",IF(SUM(J16,F16)<E16,"To Buy",IF(AND(SUM(J16,F16)>=E16,J16<>""),"Ordered",IF(AND(E16=0,F16=0,D16="B3"),"B3 Option",IF(AND(E16=0,F16=0),"Remove","To Buy")))))))))) | C16: 1 | D16: B2 | E16: =SUM(M16:S16) | F16: =SUM(T16:Z16) | G16: =IF((F16-E16)>=0,F16-E16,0) | H16: =MAX(0,$E16-$F16-$J16) | K16: 2.94 | L16: =IF(AND($H16>0,ISNUMBER($K16)),$H16*$K16,0) | P16: 1 | S16: =IF(AND(J16<>"",SUM(M16:R16)=0),J16,"") | AA16: Creature | AB16: Plant | AC16: B | AD16: 4 | AE16: Eldritch Moon | AF16: Finisher | AG16: Tap: swap target opponent's life total with this creature's toughness | AH16: Defender body | AJ16: Tuned add
A17: Brushland | B17: =IF(AND(F17<>0,E17=F17),"In Hand",IF(AND(E17<>0,E17<F17,SUM(M17:R17)=0,SUM(T17:Y17)>0),"Extra-Sub",IF(AND(E17=0,E17<F17,SUM(M17:R17)=0,SUM(T17:Y17)>0),"Bench-Sub",IF(AND(E17=0,F17>0),"Bench",IF(E17<F17,"Extra",IF(AND(J17="",E17>F17),"To Buy",IF(SUM(J17,F17)<E17,"To Buy",IF(AND(SUM(J17,F17)>=E17,J17<>""),"Ordered",IF(AND(E17=0,F17=0,D17="B3"),"B3 Option",IF(AND(E17=0,F17=0),"Remove","To Buy")))))))))) | D17: B2 | E17: =SUM(M17:S17) | F17: =SUM(T17:Z17) | G17: =IF((F17-E17)>=0,F17-E17,0) | H17: =MAX(0,$E17-$F17-$J17) | K17: 1.71 | L17: =IF(AND($H17>0,ISNUMBER($K17)),$H17*$K17,0) | S17: =IF(AND(J17<>"",SUM(M17:R17)=0),J17,"") | AA17: Land | AC17: L | AD17: 0 | AE17: Ice Age | AF17: Land | AG17: Taps for {C}, or {G}/{W} at the cost of 1 damage to you | AJ17: Bench sub available in D3: Drowned Catacomb (2026-09-02); D3 target removed 2026-09-02 (bench sub in place)
A18: Colfenor, the Last Yew | B18: =IF(AND(F18<>0,E18=F18),"In Hand",IF(AND(E18<>0,E18<F18,SUM(M18:R18)=0,SUM(T18:Y18)>0),"Extra-Sub",IF(AND(E18=0,E18<F18,SUM(M18:R18)=0,SUM(T18:Y18)>0),"Bench-Sub",IF(AND(E18=0,F18>0),"Bench",IF(E18<F18,"Extra",IF(AND(J18="",E18>F18),"To Buy",IF(SUM(J18,F18)<E18,"To Buy",IF(AND(SUM(J18,F18)>=E18,J18<>""),"Ordered",IF(AND(E18=0,F18=0,D18="B3"),"B3 Option",IF(AND(E18=0,F18=0),"Remove","To Buy")))))))))) | D18: B2 | E18: =SUM(M18:S18) | F18: =SUM(T18:Z18) | G18: =IF((F18-E18)>=0,F18-E18,0) | H18: =MAX(0,$E18-$F18-$J18) | K18: 0.54 | L18: =IF(AND($H18>0,ISNUMBER($K18)),$H18*$K18,0) | S18: =IF(AND(J18<>"",SUM(M18:R18)=0),J18,"") | AA18: Legendary Creature | AB18: Treefolk Shaman | AC18: Multi | AD18: 6 | AE18: Commander Legends | AF18: Recursion | AG18: Returns a creature card with lesser toughness from graveyard to hand when it or another creature you control dies | AH18: Reach, vigilance body | AJ18: Tuned add; Bench sub available in D4: Sun Titan (2026-09-02); D4 target removed 2026-09-02 (bench sub in place)
A19: Concealed Courtyard | B19: =IF(AND(F19<>0,E19=F19),"In Hand",IF(AND(E19<>0,E19<F19,SUM(M19:R19)=0,SUM(T19:Y19)>0),"Extra-Sub",IF(AND(E19=0,E19<F19,SUM(M19:R19)=0,SUM(T19:Y19)>0),"Bench-Sub",IF(AND(E19=0,F19>0),"Bench",IF(E19<F19,"Extra",IF(AND(J19="",E19>F19),"To Buy",IF(SUM(J19,F19)<E19,"To Buy",IF(AND(SUM(J19,F19)>=E19,J19<>""),"Ordered",IF(AND(E19=0,F19=0,D19="B3"),"B3 Option",IF(AND(E19=0,F19=0),"Remove","To Buy")))))))))) | D19: B2 | E19: =SUM(M19:S19) | F19: =SUM(T19:Z19) | G19: =IF((F19-E19)>=0,F19-E19,0) | H19: =MAX(0,$E19-$F19-$J19) | K19: 1 | L19: =IF(AND($H19>0,ISNUMBER($K19)),$H19*$K19,0) | S19: =IF(AND(J19<>"",SUM(M19:R19)=0),J19,"") | AA19: Land | AC19: L | AD19: 0 | AE19: Kaladesh | AF19: Land | AG19: Taps for {W} or {B} | AH19: Enters tapped unless you control two or fewer other lands | AJ19: Bench sub available in D5: Isolated Chapel (2026-09-02); D5 target removed 2026-09-02 (bench sub in place)
A20: Costly Plunder | B20: =IF(AND(F20<>0,E20=F20),"In Hand",IF(AND(E20<>0,E20<F20,SUM(M20:R20)=0,SUM(T20:Y20)>0),"Extra-Sub",IF(AND(E20=0,E20<F20,SUM(M20:R20)=0,SUM(T20:Y20)>0),"Bench-Sub",IF(AND(E20=0,F20>0),"Bench",IF(E20<F20,"Extra",IF(AND(J20="",E20>F20),"To Buy",IF(SUM(J20,F20)<E20,"To Buy",IF(AND(SUM(J20,F20)>=E20,J20<>""),"Ordered",IF(AND(E20=0,F20=0,D20="B3"),"B3 Option",IF(AND(E20=0,F20=0),"Remove","To Buy")))))))))) | D20: B2 | E20: =SUM(M20:S20) | F20: =SUM(T20:Z20) | G20: =IF((F20-E20)>=0,F20-E20,0) | H20: =MAX(0,$E20-$F20-$J20) | K20: 0.24 | L20: =IF(AND($H20>0,ISNUMBER($K20)),$H20*$K20,0) | S20: =IF(AND(J20<>"",SUM(M20:R20)=0),J20,"") | AA20: Instant | AC20: B | AD20: 2 | AE20: Ixalan | AF20: Sacrifice Outlet | AG20: Sacrifice an artifact or creature to draw two cards | AJ20: Cut in Tuned; D5 target removed 2026-09-02: replaced by Tuned upgrade Ossification (within $2)
A21: Doomed Traveler | B21: =IF(AND(F21<>0,E21=F21),"In Hand",IF(AND(E21<>0,E21<F21,SUM(M21:R21)=0,SUM(T21:Y21)>0),"Extra-Sub",IF(AND(E21=0,E21<F21,SUM(M21:R21)=0,SUM(T21:Y21)>0),"Bench-Sub",IF(AND(E21=0,F21>0),"Bench",IF(E21<F21,"Extra",IF(AND(J21="",E21>F21),"To Buy",IF(SUM(J21,F21)<E21,"To Buy",IF(AND(SUM(J21,F21)>=E21,J21<>""),"Ordered",IF(AND(E21=0,F21=0,D21="B3"),"B3 Option",IF(AND(E21=0,F21=0),"Remove","To Buy")))))))))) | D21: B2 | E21: =SUM(M21:S21) | F21: =SUM(T21:Z21) | G21: =IF((F21-E21)>=0,F21-E21,0) | H21: =MAX(0,$E21-$F21-$J21) | K21: 0.09 | L21: =IF(AND($H21>0,ISNUMBER($K21)),$H21*$K21,0) | S21: =IF(AND(J21<>"",SUM(M21:R21)=0),J21,"") | AA21: Creature | AB21: Human Soldier | AC21: W | AD21: 1 | AE21: Innistrad | AF21: Token Producer | AG21: Creates a 1/1 flying Spirit token when it dies | AJ21: Bench sub available in D5: Lake-town Lookout (2026-09-02); D5 target removed 2026-09-02 (bench sub in place)
A22: Eternal Witness | B22: =IF(AND(F22<>0,E22=F22),"In Hand",IF(AND(E22<>0,E22<F22,SUM(M22:R22)=0,SUM(T22:Y22)>0),"Extra-Sub",IF(AND(E22=0,E22<F22,SUM(M22:R22)=0,SUM(T22:Y22)>0),"Bench-Sub",IF(AND(E22=0,F22>0),"Bench",IF(E22<F22,"Extra",IF(AND(J22="",E22>F22),"To Buy",IF(SUM(J22,F22)<E22,"To Buy",IF(AND(SUM(J22,F22)>=E22,J22<>""),"Ordered",IF(AND(E22=0,F22=0,D22="B3"),"B3 Option",IF(AND(E22=0,F22=0),"Remove","To Buy")))))))))) | D22: B2 | E22: =SUM(M22:S22) | F22: =SUM(T22:Z22) | G22: =IF((F22-E22)>=0,F22-E22,0) | H22: =MAX(0,$E22-$F22-$J22) | K22: 2.52 | L22: =IF(AND($H22>0,ISNUMBER($K22)),$H22*$K22,0) | S22: =IF(AND(J22<>"",SUM(M22:R22)=0),J22,"") | AA22: Creature | AB22: Human Shaman | AC22: G | AD22: 3 | AE22: Fifth Dawn | AF22: Recursion | AG22: Returns target card from your graveyard to hand when it enters | AJ22: Tuned add; Bench sub available in D2: Dundoolin Weaver (2026-09-02); D2 target removed 2026-09-02 (bench sub in place)
A23: Fire Diamond | B23: =IF(AND(F23<>0,E23=F23),"In Hand",IF(AND(E23<>0,E23<F23,SUM(M23:R23)=0,SUM(T23:Y23)>0),"Extra-Sub",IF(AND(E23=0,E23<F23,SUM(M23:R23)=0,SUM(T23:Y23)>0),"Bench-Sub",IF(AND(E23=0,F23>0),"Bench",IF(E23<F23,"Extra",IF(AND(J23="",E23>F23),"To Buy",IF(SUM(J23,F23)<E23,"To Buy",IF(AND(SUM(J23,F23)>=E23,J23<>""),"Ordered",IF(AND(E23=0,F23=0,D23="B3"),"B3 Option",IF(AND(E23=0,F23=0),"Remove","To Buy")))))))))) | D23: B2 | E23: =SUM(M23:S23) | F23: =SUM(T23:Z23) | G23: =IF((F23-E23)>=0,F23-E23,0) | H23: =MAX(0,$E23-$F23-$J23) | K23: 0.36 | L23: =IF(AND($H23>0,ISNUMBER($K23)),$H23*$K23,0) | S23: =IF(AND(J23<>"",SUM(M23:R23)=0),J23,"") | AA23: Artifact | AC23: R | AD23: 2 | AE23: Mirage | AF23: Mana Rock | AG23: Taps for {R} (enters tapped) | AJ23: Cut in Tuned; D6 target removed 2026-09-02 (bench sub Sword of the Animist in place)
A24: Gather the Townsfolk | B24: =IF(AND(F24<>0,E24=F24),"In Hand",IF(AND(E24<>0,E24<F24,SUM(M24:R24)=0,SUM(T24:Y24)>0),"Extra-Sub",IF(AND(E24=0,E24<F24,SUM(M24:R24)=0,SUM(T24:Y24)>0),"Bench-Sub",IF(AND(E24=0,F24>0),"Bench",IF(E24<F24,"Extra",IF(AND(J24="",E24>F24),"To Buy",IF(SUM(J24,F24)<E24,"To Buy",IF(AND(SUM(J24,F24)>=E24,J24<>""),"Ordered",IF(AND(E24=0,F24=0,D24="B3"),"B3 Option",IF(AND(E24=0,F24=0),"Remove","To Buy")))))))))) | D24: B2 | E24: =SUM(M24:S24) | F24: =SUM(T24:Z24) | G24: =IF((F24-E24)>=0,F24-E24,0) | H24: =MAX(0,$E24-$F24-$J24) | K24: 0.13 | L24: =IF(AND($H24>0,ISNUMBER($K24)),$H24*$K24,0) | S24: =IF(AND(J24<>"",SUM(M24:R24)=0),J24,"") | AA24: Sorcery | AC24: W | AD24: 2 | AE24: Dark Ascension | AF24: Token Producer | AG24: Creates two 1/1 Human tokens (five instead if you have 5 or less life) | AJ24: Bench sub available in D5: Clachan Festival (2026-09-02); D5 target removed 2026-09-02 (bench sub in place)
A25: Goblin Motivator | B25: =IF(AND(F25<>0,E25=F25),"In Hand",IF(AND(E25<>0,E25<F25,SUM(M25:R25)=0,SUM(T25:Y25)>0),"Extra-Sub",IF(AND(E25=0,E25<F25,SUM(M25:R25)=0,SUM(T25:Y25)>0),"Bench-Sub",IF(AND(E25=0,F25>0),"Bench",IF(E25<F25,"Extra",IF(AND(J25="",E25>F25),"To Buy",IF(SUM(J25,F25)<E25,"To Buy",IF(AND(SUM(J25,F25)>=E25,J25<>""),"Ordered",IF(AND(E25=0,F25=0,D25="B3"),"B3 Option",IF(AND(E25=0,F25=0),"Remove","To Buy")))))))))) | D25: B2 | E25: =SUM(M25:S25) | F25: =SUM(T25:Z25) | G25: =IF((F25-E25)>=0,F25-E25,0) | H25: =MAX(0,$E25-$F25-$J25) | K25: 0.26 | L25: =IF(AND($H25>0,ISNUMBER($K25)),$H25*$K25,0) | S25: =IF(AND(J25<>"",SUM(M25:R25)=0),J25,"") | AA25: Creature | AB25: Goblin Warrior | AC25: R | AD25: 1 | AE25: Core Set 2019 | AF25: Haste Enabler | AG25: Tap: target creature gains haste until end of turn | AJ25: Cut in Tuned; D6 target removed 2026-09-02: replaced by Tuned upgrade Purphoros's Intervention (within $2)
A26: Goblin Oriflamme | B26: =IF(AND(F26<>0,E26=F26),"In Hand",IF(AND(E26<>0,E26<F26,SUM(M26:R26)=0,SUM(T26:Y26)>0),"Extra-Sub",IF(AND(E26=0,E26<F26,SUM(M26:R26)=0,SUM(T26:Y26)>0),"Bench-Sub",IF(AND(E26=0,F26>0),"Bench",IF(E26<F26,"Extra",IF(AND(J26="",E26>F26),"To Buy",IF(SUM(J26,F26)<E26,"To Buy",IF(AND(SUM(J26,F26)>=E26,J26<>""),"Ordered",IF(AND(E26=0,F26=0,D26="B3"),"B3 Option",IF(AND(E26=0,F26=0),"Remove","To Buy")))))))))) | D26: B2 | E26: =SUM(M26:S26) | F26: =SUM(T26:Z26) | G26: =IF((F26-E26)>=0,F26-E26,0) | H26: =MAX(0,$E26-$F26-$J26) | K26: 0.53 | L26: =IF(AND($H26>0,ISNUMBER($K26)),$H26*$K26,0) | S26: =IF(AND(J26<>"",SUM(M26:R26)=0),J26,"") | AA26: Enchantment | AC26: R | AD26: 2 | AE26: Modern Horizons | AF26: Lord/Anthem | AG26: Attacking creatures you control get +1/+0 | AJ26: Cut in Tuned; D6 target removed 2026-09-02: replaced by Tuned upgrade Goblin Rabblemaster (within $2)
A27: Great Furnace | B27: =IF(AND(F27<>0,E27=F27),"In Hand",IF(AND(E27<>0,E27<F27,SUM(M27:R27)=0,SUM(T27:Y27)>0),"Extra-Sub",IF(AND(E27=0,E27<F27,SUM(M27:R27)=0,SUM(T27:Y27)>0),"Bench-Sub",IF(AND(E27=0,F27>0),"Bench",IF(E27<F27,"Extra",IF(AND(J27="",E27>F27),"To Buy",IF(SUM(J27,F27)<E27,"To Buy",IF(AND(SUM(J27,F27)>=E27,J27<>""),"Ordered",IF(AND(E27=0,F27=0,D27="B3"),"B3 Option",IF(AND(E27=0,F27=0),"Remove","To Buy")))))))))) | D27: B2 | E27: =SUM(M27:S27) | F27: =SUM(T27:Z27) | G27: =IF((F27-E27)>=0,F27-E27,0) | H27: =MAX(0,$E27-$F27-$J27) | K27: 2.43 | L27: =IF(AND($H27>0,ISNUMBER($K27)),$H27*$K27,0) | S27: =IF(AND(J27<>"",SUM(M27:R27)=0),J27,"") | AA27: Artifact Land | AC27: R | AD27: 0 | AE27: Mirrodin | AF27: Land | AG27: Taps for {R} | AJ27: Bench sub available in D6: Mountain (2026-09-02); D6 target removed 2026-09-02 (bench sub in place)
A28: Hunted Witness | B28: =IF(AND(F28<>0,E28=F28),"In Hand",IF(AND(E28<>0,E28<F28,SUM(M28:R28)=0,SUM(T28:Y28)>0),"Extra-Sub",IF(AND(E28=0,E28<F28,SUM(M28:R28)=0,SUM(T28:Y28)>0),"Bench-Sub",IF(AND(E28=0,F28>0),"Bench",IF(E28<F28,"Extra",IF(AND(J28="",E28>F28),"To Buy",IF(SUM(J28,F28)<E28,"To Buy",IF(AND(SUM(J28,F28)>=E28,J28<>""),"Ordered",IF(AND(E28=0,F28=0,D28="B3"),"B3 Option",IF(AND(E28=0,F28=0),"Remove","To Buy")))))))))) | D28: B2 | E28: =SUM(M28:S28) | F28: =SUM(T28:Z28) | G28: =IF((F28-E28)>=0,F28-E28,0) | H28: =MAX(0,$E28-$F28-$J28) | K28: 0.29 | L28: =IF(AND($H28>0,ISNUMBER($K28)),$H28*$K28,0) | S28: =IF(AND(J28<>"",SUM(M28:R28)=0),J28,"") | AA28: Creature | AB28: Human | AC28: W | AD28: 1 | AE28: Guilds of Ravnica | AF28: Token Producer | AG28: Creates a 1/1 lifelink Soldier token when it dies | AJ28: Bench sub available in D5: Pretending Poxbearers (2026-09-02); D5 target removed 2026-09-02 (bench sub in place)
A29: Inspiring Overseer | B29: =IF(AND(F29<>0,E29=F29),"In Hand",IF(AND(E29<>0,E29<F29,SUM(M29:R29)=0,SUM(T29:Y29)>0),"Extra-Sub",IF(AND(E29=0,E29<F29,SUM(M29:R29)=0,SUM(T29:Y29)>0),"Bench-Sub",IF(AND(E29=0,F29>0),"Bench",IF(E29<F29,"Extra",IF(AND(J29="",E29>F29),"To Buy",IF(SUM(J29,F29)<E29,"To Buy",IF(AND(SUM(J29,F29)>=E29,J29<>""),"Ordered",IF(AND(E29=0,F29=0,D29="B3"),"B3 Option",IF(AND(E29=0,F29=0),"Remove","To Buy")))))))))) | D29: B2 | E29: =SUM(M29:S29) | F29: =SUM(T29:Z29) | G29: =IF((F29-E29)>=0,F29-E29,0) | H29: =MAX(0,$E29-$F29-$J29) | K29: 0.28 | L29: =IF(AND($H29>0,ISNUMBER($K29)),$H29*$K29,0) | S29: =IF(AND(J29<>"",SUM(M29:R29)=0),J29,"") | AA29: Creature | AB29: Angel Cleric | AC29: W | AD29: 3 | AE29: Streets of New Capenna | AF29: Card Draw | AG29: Gains 1 life and draws a card when it enters | AH29: Flying body | AJ29: Cut in Tuned; D5 target removed 2026-09-02: replaced by Tuned upgrade Requiem Angel (within $2)
A30: Llanowar Wastes | B30: =IF(AND(F30<>0,E30=F30),"In Hand",IF(AND(E30<>0,E30<F30,SUM(M30:R30)=0,SUM(T30:Y30)>0),"Extra-Sub",IF(AND(E30=0,E30<F30,SUM(M30:R30)=0,SUM(T30:Y30)>0),"Bench-Sub",IF(AND(E30=0,F30>0),"Bench",IF(E30<F30,"Extra",IF(AND(J30="",E30>F30),"To Buy",IF(SUM(J30,F30)<E30,"To Buy",IF(AND(SUM(J30,F30)>=E30,J30<>""),"Ordered",IF(AND(E30=0,F30=0,D30="B3"),"B3 Option",IF(AND(E30=0,F30=0),"Remove","To Buy")))))))))) | D30: B2 | E30: =SUM(M30:S30) | F30: =SUM(T30:Z30) | G30: =IF((F30-E30)>=0,F30-E30,0) | H30: =MAX(0,$E30-$F30-$J30) | K30: 0.69 | L30: =IF(AND($H30>0,ISNUMBER($K30)),$H30*$K30,0) | S30: =IF(AND(J30<>"",SUM(M30:R30)=0),J30,"") | AA30: Land | AC30: L | AD30: 0 | AE30: Apocalypse | AF30: Land | AG30: Taps for {C}, or {B}/{G} at the cost of 1 damage to you | AJ30: Bench sub available in D4: Blossoming Sands (2026-09-02); Bench sub available in D3: Arcane Sanctum (2026-09-02); D4 target removed 2026-09-02 (bench sub in place); D3 target removed 2026-09-02 (bench sub in place)
A31: Priest of Fell Rites | B31: =IF(AND(F31<>0,E31=F31),"In Hand",IF(AND(E31<>0,E31<F31,SUM(M31:R31)=0,SUM(T31:Y31)>0),"Extra-Sub",IF(AND(E31=0,E31<F31,SUM(M31:R31)=0,SUM(T31:Y31)>0),"Bench-Sub",IF(AND(E31=0,F31>0),"Bench",IF(E31<F31,"Extra",IF(AND(J31="",E31>F31),"To Buy",IF(SUM(J31,F31)<E31,"To Buy",IF(AND(SUM(J31,F31)>=E31,J31<>""),"Ordered",IF(AND(E31=0,F31=0,D31="B3"),"B3 Option",IF(AND(E31=0,F31=0),"Remove","To Buy")))))))))) | D31: B2 | E31: =SUM(M31:S31) | F31: =SUM(T31:Z31) | G31: =IF((F31-E31)>=0,F31-E31,0) | H31: =MAX(0,$E31-$F31-$J31) | K31: 0.36 | L31: =IF(AND($H31>0,ISNUMBER($K31)),$H31*$K31,0) | S31: =IF(AND(J31<>"",SUM(M31:R31)=0),J31,"") | AA31: Creature | AB31: Human Warlock | AC31: Multi | AD31: 2 | AE31: Modern Horizons 2 | AF31: Reanimation | AG31: Tap, pay 3 life, sacrifice: return target creature card from graveyard to the battlefield | AH31: Unearth {3}{W}{B} to return from graveyard with haste temporarily | AJ31: Bench sub available in D5: Unbury (2026-09-02); D5 target removed 2026-09-02 (bench sub in place)
A32: Rummaging Goblin | B32: =IF(AND(F32<>0,E32=F32),"In Hand",IF(AND(E32<>0,E32<F32,SUM(M32:R32)=0,SUM(T32:Y32)>0),"Extra-Sub",IF(AND(E32=0,E32<F32,SUM(M32:R32)=0,SUM(T32:Y32)>0),"Bench-Sub",IF(AND(E32=0,F32>0),"Bench",IF(E32<F32,"Extra",IF(AND(J32="",E32>F32),"To Buy",IF(SUM(J32,F32)<E32,"To Buy",IF(AND(SUM(J32,F32)>=E32,J32<>""),"Ordered",IF(AND(E32=0,F32=0,D32="B3"),"B3 Option",IF(AND(E32=0,F32=0),"Remove","To Buy")))))))))) | D32: B2 | E32: =SUM(M32:S32) | F32: =SUM(T32:Z32) | G32: =IF((F32-E32)>=0,F32-E32,0) | H32: =MAX(0,$E32-$F32-$J32) | K32: 0.2 | L32: =IF(AND($H32>0,ISNUMBER($K32)),$H32*$K32,0) | S32: =IF(AND(J32<>"",SUM(M32:R32)=0),J32,"") | AA32: Creature | AB32: Goblin Rogue | AC32: R | AD32: 3 | AE32: Magic 2013 | AF32: Discard/Looting | AG32: Tap, discard a card: draw a card | AJ32: Cut in Tuned; Bench sub available in D6: Gundabad Opportunist (2026-09-02); D6 target removed 2026-09-02 (bench sub in place)
A33: Shineshadow Snarl | B33: =IF(AND(F33<>0,E33=F33),"In Hand",IF(AND(E33<>0,E33<F33,SUM(M33:R33)=0,SUM(T33:Y33)>0),"Extra-Sub",IF(AND(E33=0,E33<F33,SUM(M33:R33)=0,SUM(T33:Y33)>0),"Bench-Sub",IF(AND(E33=0,F33>0),"Bench",IF(E33<F33,"Extra",IF(AND(J33="",E33>F33),"To Buy",IF(SUM(J33,F33)<E33,"To Buy",IF(AND(SUM(J33,F33)>=E33,J33<>""),"Ordered",IF(AND(E33=0,F33=0,D33="B3"),"B3 Option",IF(AND(E33=0,F33=0),"Remove","To Buy")))))))))) | D33: B2 | E33: =SUM(M33:S33) | F33: =SUM(T33:Z33) | G33: =IF((F33-E33)>=0,F33-E33,0) | H33: =MAX(0,$E33-$F33-$J33) | K33: 0.33 | L33: =IF(AND($H33>0,ISNUMBER($K33)),$H33*$K33,0) | S33: =IF(AND(J33<>"",SUM(M33:R33)=0),J33,"") | AA33: Land | AC33: L | AD33: 0 | AE33: Strixhaven: School of Mages | AF33: Land | AG33: Taps for {W} or {B} | AH33: Enters untapped if you reveal a Plains or Swamp | AJ33: Bench sub available in D5: Plains (2026-09-02); D5 target removed 2026-09-02 (bench sub in place)
A34: Sign in Blood | B34: =IF(AND(F34<>0,E34=F34),"In Hand",IF(AND(E34<>0,E34<F34,SUM(M34:R34)=0,SUM(T34:Y34)>0),"Extra-Sub",IF(AND(E34=0,E34<F34,SUM(M34:R34)=0,SUM(T34:Y34)>0),"Bench-Sub",IF(AND(E34=0,F34>0),"Bench",IF(E34<F34,"Extra",IF(AND(J34="",E34>F34),"To Buy",IF(SUM(J34,F34)<E34,"To Buy",IF(AND(SUM(J34,F34)>=E34,J34<>""),"Ordered",IF(AND(E34=0,F34=0,D34="B3"),"B3 Option",IF(AND(E34=0,F34=0),"Remove","To Buy")))))))))) | D34: B2 | E34: =SUM(M34:S34) | F34: =SUM(T34:Z34) | G34: =IF((F34-E34)>=0,F34-E34,0) | H34: =MAX(0,$E34-$F34-$J34) | K34: 3.67 | L34: =IF(AND($H34>0,ISNUMBER($K34)),$H34*$K34,0) | S34: =IF(AND(J34<>"",SUM(M34:R34)=0),J34,"") | AA34: Sorcery | AC34: B | AD34: 2 | AE34: Magic 2010 | AF34: Card Draw | AG34: Target player draws two cards and loses 2 life | AJ34: Bench sub available in D5: Secret Rendezvous (2026-09-02); D5 target removed 2026-09-02 (bench sub in place)
A35: Silverquill Campus | B35: =IF(AND(F35<>0,E35=F35),"In Hand",IF(AND(E35<>0,E35<F35,SUM(M35:R35)=0,SUM(T35:Y35)>0),"Extra-Sub",IF(AND(E35=0,E35<F35,SUM(M35:R35)=0,SUM(T35:Y35)>0),"Bench-Sub",IF(AND(E35=0,F35>0),"Bench",IF(E35<F35,"Extra",IF(AND(J35="",E35>F35),"To Buy",IF(SUM(J35,F35)<E35,"To Buy",IF(AND(SUM(J35,F35)>=E35,J35<>""),"Ordered",IF(AND(E35=0,F35=0,D35="B3"),"B3 Option",IF(AND(E35=0,F35=0),"Remove","To Buy")))))))))) | D35: B2 | E35: =SUM(M35:S35) | F35: =SUM(T35:Z35) | G35: =IF((F35-E35)>=0,F35-E35,0) | H35: =MAX(0,$E35-$F35-$J35) | K35: 0.29 | L35: =IF(AND($H35>0,ISNUMBER($K35)),$H35*$K35,0) | S35: =IF(AND(J35<>"",SUM(M35:R35)=0),J35,"") | AA35: Land | AC35: L | AD35: 0 | AE35: Strixhaven: School of Mages | AF35: Land | AG35: Taps for {W} or {B} (enters tapped) | AH35: {4}, tap: Scry 1 | AJ35: Bench sub available in D5: Swamp (2026-09-02); D5 target removed 2026-09-02 (bench sub in place)
A36: Slaughter Specialist | B36: =IF(AND(F36<>0,E36=F36),"In Hand",IF(AND(E36<>0,E36<F36,SUM(M36:R36)=0,SUM(T36:Y36)>0),"Extra-Sub",IF(AND(E36=0,E36<F36,SUM(M36:R36)=0,SUM(T36:Y36)>0),"Bench-Sub",IF(AND(E36=0,F36>0),"Bench",IF(E36<F36,"Extra",IF(AND(J36="",E36>F36),"To Buy",IF(SUM(J36,F36)<E36,"To Buy",IF(AND(SUM(J36,F36)>=E36,J36<>""),"Ordered",IF(AND(E36=0,F36=0,D36="B3"),"B3 Option",IF(AND(E36=0,F36=0),"Remove","To Buy")))))))))) | D36: B2 | E36: =SUM(M36:S36) | F36: =SUM(T36:Z36) | G36: =IF((F36-E36)>=0,F36-E36,0) | H36: =MAX(0,$E36-$F36-$J36) | K36: 0.88 | L36: =IF(AND($H36>0,ISNUMBER($K36)),$H36*$K36,0) | S36: =IF(AND(J36<>"",SUM(M36:R36)=0),J36,"") | AA36: Creature | AB36: Vampire Warrior | AC36: B | AD36: 2 | AE36: Innistrad: Midnight Hunt | AF36: Toughness Payoff | AG36: Gives each opponent a 1/1 Human token when it enters | AH36: Gets a +1/+1 counter whenever an opponent's creature dies | AJ36: Tuned add; Bench sub available in D4: Canopy Gargantuan (2026-09-02); D4 target removed 2026-09-02 (bench sub in place)
