Workbook

Sheet How to use
A1: MTG Deck Decision Matrix
A2: Six decks · 100 lineup slots each · eleven candidate builds per slot · every simulated column backed by its own Monte Carlo run.
A4: The column hierarchy
A5: Site ladder — as published | B5: Base → Tuned → Enhance → Max
A6: Simulation-improved (Monte Carlo) | B6: Tuned-2 → Enhance-2 → Max-2
A7: Fun-weighted engine v2.1 | B7: Fun Tuned → Fun Max
A8: Alternative commander | B8: Alt Tuned → Alt Max
A10: Site ladder — as published
A11: Base is the starting shell you already own. Tuned adds every required purchase. Enhance adds the site's cheap side-grade tier. Max is the site's curated Tier 3 ceiling. These are the catalog's own lists — Tuned is the only one of the four that was ever simulated in this exact form.
A13: Simulation-improved (Monte Carlo)
A14: Tuned-2, Enhance-2 and Max-2 are the improved sets of cards the Monte Carlo optimizer found: it measured where each build actually lost, proposed swaps, re-measured, and kept only what still held up on thousands of games the optimizer never saw. Enhance-2 and Max-2 were additionally re-simulated as assembled lists, because assembling a list from separate evidence is not the same as measuring that exact list.
A16: Fun-weighted engine v2.1
A17: The same six decks re-optimized after three engine corrections (toughness-as-damage creatures, planeswalker commanders, multicolour land parsing) and a scoring change: raw win rate was cut from 0.40 to 0.30 of the score and a fun/participation signal given 0.10. These builds are tuned for games you actually get to play in, not purely for winning.
A19: Alternative commander
A20: Decks 1, 3 and 5 only — Teneb, Hazel and Iroas, each measured on that deck's own 99 cards and then re-optimized around the new commander. Read the Summary tab's alternative-commander block before adopting one; the case is much stronger for some than for others.
A22: How to decide
A23: Work down a deck sheet. Each row is one lineup slot. Set FINAL PICK to the build whose card you want in that slot — the Final Card, its price and the reason it moved all resolve automatically. The Final List tab collects every choice into a flat table for the session updating the web app.
A25: A caution worth reading
A26: The engine is a model, not a rules engine. It cannot see proliferate, trigger doubling, devotion, or most commander-specific synergy text. Where that materially changes a recommendation, the Summary and Notes tabs say so explicitly rather than letting the number stand alone.

Sheet Summary
A1: Build metrics — what backs each column
A2: Every simulated column below reports the games behind it and whether its gain survived a holdout of seeds the optimizer never saw. Blank = a published list with no simulation of its own.
A3: DO NOT compare scores across engine generations. Tuned and Tuned-2 were measured on the v1 engine (three opponent archetypes, win rate weighted 0.40). Enhance-2 and Max-2 were re-verified on v1 as assembled lists. Fun and Alt columns ran on v2.1 (nine archetypes, win rate 0.30, fun 0.10, three combat fixes). v2.1 scores are systematically lower because the opponent field is harder — that is not the deck getting worse. Compare only within a generation.
A4: Deck | B4: Build | C4: Group | D4: Games | E4: Holdout games | F4: Score | G4: Win % | H4: Fun % | I4: Avg win turn | J4: Cmdr turn | K4: Screw % | L4: Interaction | M4: Verdict | N4: Swaps | O4: What this column is
A5: 1o · Ancestral Bulwark | B5: Base | C5: Site ladder — as published | O5: published
A6: 1o · Ancestral Bulwark | B6: Tuned | C6: Site ladder — as published | D6: 20000 | E6: 5000 | F6: 80.3 | G6: 0.4322 | I6: 11.855622 | J6: 5.1371183 | K6: 0.0552 | L6: 0.36832 | M6: confirmed | N6: 5 | O6: published + simulated (v1 engine)
A7: 1o · Ancestral Bulwark | B7: Enhance | C7: Site ladder — as published | O7: published
A8: 1o · Ancestral Bulwark | B8: Max | C8: Site ladder — as published | O8: published
A9: 1o · Ancestral Bulwark | B9: Tuned-2 | C9: Simulation-improved (Monte Carlo) | D9: 20000 | E9: 5000 | F9: 80.3 | G9: 0.4322 | I9: 11.855622 | J9: 5.1371183 | K9: 0.0552 | L9: 0.36832 | M9: confirmed | N9: 5 | O9: simulation-improved (v1 engine)
A10: 1o · Ancestral Bulwark | B10: Enhance-2 | C10: Simulation-improved (Monte Carlo) | D10: 13000 | E10: 5000 | F10: 77.9 | G10: 0.448 | I10: 11.791518 | J10: 5.2206641 | K10: 0.0572 | L10: 0.22744 | M10: no-change | N10: 0 | O10: simulation-improved, then independently re-verified as an assembled list
A11: 1o · Ancestral Bulwark | B11: Max-2 | C11: Simulation-improved (Monte Carlo) | D11: 16000 | E11: 5000 | F11: 77.7 | G11: 0.4466 | I11: 11.834304 | J11: 5.2291796 | K11: 0.0594 | L11: 0.24564 | M11: within-noise | N11: 2 | O11: simulation-improved, then independently re-verified as an assembled list
A12: 1o · Ancestral Bulwark | B12: Fun Tuned | C12: Fun-weighted engine v2.1 | D12: 20000 | E12: 5000 | F12: 85.8 | G12: 0.4728 | H12: 0.9994 | I12: 11.304569 | J12: 4.8862348 | K12: 0.0508 | L12: 0.4146 | M12: confirmed | N12: 4 | O12: fun-weighted engine v2.1 (9 opponent archetypes, fun blended into scoring, combat fixes)
A13: 1o · Ancestral Bulwark | B13: Fun Max | C13: Fun-weighted engine v2.1 | D13: 22000 | E13: 5000 | F13: 83.3 | G13: 0.4774 | H13: 0.9964 | I13: 11.410557 | J13: 5.271063 | K13: 0.1042 | L13: 0.43544 | M13: confirmed | N13: 10 | O13: fun-weighted engine v2.1 (9 opponent archetypes, fun blended into scoring, combat fixes)
A14: 1o · Ancestral Bulwark | B14: Alt Tuned | C14: Alternative commander | D14: 20000 | E14: 5000 | F14: 86.3 | G14: 0.4852 | H14: 0.999 | I14: 11.27906 | J14: 5.6097411 | K14: 0.0508 | L14: 0.40152 | M14: confirmed | N14: 4 | O14: alternative commander (Teneb, the Harvester) on the same 99, v2.1 engine
A15: 1o · Ancestral Bulwark | B15: Alt Max | C15: Alternative commander | D15: 24000 | E15: 5000 | F15: 84.6 | G15: 0.4746 | H15: 0.996 | I15: 11.340076 | J15: 5.9989243 | K15: 0.0844 | L15: 0.41532 | M15: confirmed | N15: 15 | O15: alternative commander (Teneb, the Harvester) on the same 99, v2.1 engine
A17: 2c · Proliferate Council | B17: Base | C17: Site ladder — as published | O17: published
A18: 2c · Proliferate Council | B18: Tuned | C18: Site ladder — as published | D18: 22000 | E18: 5000 | F18: 86.1 | G18: 0.505 | I18: 11.41505 | J18: 4.7921968 | K18: 0.0632 | L18: 0.37736 | M18: confirmed | N18: 10 | O18: published + simulated (v1 engine)
A19: 2c · Proliferate Council | B19: Enhance | C19: Site ladder — as published | O19: published
A20: 2c · Proliferate Council | B20: Max | C20: Site ladder — as published | O20: published
A21: 2c · Proliferate Council | B21: Tuned-2 | C21: Simulation-improved (Monte Carlo) | D21: 22000 | E21: 5000 | F21: 86.1 | G21: 0.505 | I21: 11.41505 | J21: 4.7921968 | K21: 0.0632 | L21: 0.37736 | M21: confirmed | N21: 10 | O21: simulation-improved (v1 engine)
A22: 2c · Proliferate Council | B22: Enhance-2 | C22: Simulation-improved (Monte Carlo) | D22: 20000 | E22: 5000 | F22: 84.6 | G22: 0.4816 | I22: 11.436462 | J22: 4.7976319 | K22: 0.0638 | L22: 0.38504 | M22: within-noise | N22: 5 | O22: simulation-improved, then independently re-verified as an assembled list
A23: 2c · Proliferate Council | B23: Max-2 | C23: Simulation-improved (Monte Carlo) | D23: 20000 | E23: 5000 | F23: 84.6 | G23: 0.4816 | I23: 11.436462 | J23: 4.7976319 | K23: 0.0638 | L23: 0.38504 | M23: within-noise | N23: 5 | O23: simulation-improved, then independently re-verified as an assembled list
A24: 2c · Proliferate Council | B24: Fun Tuned | C24: Fun-weighted engine v2.1 | D24: 20000 | E24: 5000 | F24: 75.3 | G24: 0.2934 | H24: 0.9991 | I24: 12.09816 | J24: 4.406838 | K24: 0.0436 | L24: 0.5392 | M24: confirmed | N24: 5 | O24: fun-weighted engine v2.1 (9 opponent archetypes, fun blended into scoring, combat fixes)
A25: 2c · Proliferate Council | B25: Fun Max | C25: Fun-weighted engine v2.1 | D25: 20000 | E25: 5000 | F25: 75.2 | G25: 0.3006 | H25: 0.9986 | I25: 12.220226 | J25: 4.3071169 | K25: 0.058 | L25: 0.56256 | M25: confirmed | N25: 5 | O25: fun-weighted engine v2.1 (9 opponent archetypes, fun blended into scoring, combat fixes)
A27: 3e · Golgari Land Engine | B27: Base | C27: Site ladder — as published | O27: published
A28: 3e · Golgari Land Engine | B28: Tuned | C28: Site ladder — as published | D28: 24000 | E28: 5000 | F28: 80.2 | G28: 0.4342 | I28: 12.062183 | J28: 4.7325629 | K28: 0.051 | L28: 0.3518 | M28: confirmed | N28: 13 | O28: published + simulated (v1 engine)
A29: 3e · Golgari Land Engine | B29: Enhance | C29: Site ladder — as published | O29: published
A30: 3e · Golgari Land Engine | B30: Max | C30: Site ladder — as published | O30: published
A31: 3e · Golgari Land Engine | B31: Tuned-2 | C31: Simulation-improved (Monte Carlo) | D31: 24000 | E31: 5000 | F31: 80.2 | G31: 0.4342 | I31: 12.062183 | J31: 4.7325629 | K31: 0.051 | L31: 0.3518 | M31: confirmed | N31: 13 | O31: simulation-improved (v1 engine)
A32: 3e · Golgari Land Engine | B32: Enhance-2 | C32: Simulation-improved (Monte Carlo) | D32: 7000 | E32: 5000 | F32: 70.6 | G32: 0.3996 | I32: 12.029029 | J32: 4.7151305 | K32: 0.054 | L32: 0.10452 | M32: no-change | N32: 0 | O32: simulation-improved, then independently re-verified as an assembled list
A33: 3e · Golgari Land Engine | B33: Max-2 | C33: Simulation-improved (Monte Carlo) | D33: 7000 | E33: 5000 | F33: 70.6 | G33: 0.3996 | I33: 12.029029 | J33: 4.7151305 | K33: 0.054 | L33: 0.10452 | M33: no-change | N33: 0 | O33: simulation-improved, then independently re-verified as an assembled list
A34: 3e · Golgari Land Engine | B34: Fun Tuned | C34: Fun-weighted engine v2.1 | D34: 22000 | E34: 5000 | F34: 74 | G34: 0.2766 | H34: 0.9989 | I34: 12.237889 | J34: 4.6077326 | K34: 0.0382 | L34: 0.39724 | M34: confirmed | N34: 10 | O34: fun-weighted engine v2.1 (9 opponent archetypes, fun blended into scoring, combat fixes)
A35: 3e · Golgari Land Engine | B35: Fun Max | C35: Fun-weighted engine v2.1 | D35: 22000 | E35: 5000 | F35: 72.2 | G35: 0.2668 | H35: 0.999 | I35: 12.17916 | J35: 4.4341444 | K35: 0.029 | L35: 0.35572 | M35: within-noise | N35: 10 | O35: fun-weighted engine v2.1 (9 opponent archetypes, fun blended into scoring, combat fixes)
A36: 3e · Golgari Land Engine | B36: Alt Tuned | C36: Alternative commander | D36: 22000 | E36: 5000 | F36: 79.1 | G36: 0.346 | H36: 0.9994 | I36: 11.93237 | J36: 4.0439054 | K36: 0.034 | L36: 0.4164 | M36: confirmed | N36: 10 | O36: alternative commander (Hazel of the Rootbloom) on the same 99, v2.1 engine
A37: 3e · Golgari Land Engine | B37: Alt Max | C37: Alternative commander | D37: 24000 | E37: 5000 | F37: 78.8 | G37: 0.351 | H37: 0.9991 | I37: 11.864387 | J37: 3.9857573 | K37: 0.031 | L37: 0.40448 | M37: confirmed | N37: 12 | O37: alternative commander (Hazel of the Rootbloom) on the same 99, v2.1 engine
A39: 4c · Bant Walls | B39: Base | C39: Site ladder — as published | O39: published
A40: 4c · Bant Walls | B40: Tuned | C40: Site ladder — as published | D40: 22000 | E40: 5000 | F40: 61.3 | G40: 0.2932 | I40: 12.966576 | J40: 4.8958378 | K40: 0.1072 | L40: 0.2632 | M40: confirmed | N40: 10 | O40: published + simulated (v1 engine)
A41: 4c · Bant Walls | B41: Enhance | C41: Site ladder — as published | O41: published
A42: 4c · Bant Walls | B42: Max | C42: Site ladder — as published | O42: published
A43: 4c · Bant Walls | B43: Tuned-2 | C43: Simulation-improved (Monte Carlo) | D43: 22000 | E43: 5000 | F43: 61.3 | G43: 0.2932 | I43: 12.966576 | J43: 4.8958378 | K43: 0.1072 | L43: 0.2632 | M43: confirmed | N43: 10 | O43: simulation-improved (v1 engine)
...

Sheet 1o Ancestral Bulwark
A1: Ancestral Bulwark — Betor, Ancestor's Voice
A2: Deck slot 1 · variant 1o · 100 lineup slots · alternative commander tested: Teneb, the Harvester
B4: Site ladder — as published | F4: Simulation-improved (Monte Carlo) | I4: Fun-weighted engine v2.1 | K4: Alternative commander
A5: Slot | B5: Base | C5: Tuned | D5: Enhance | E5: Max | F5: Tuned-2 | G5: Enhance-2 | H5: Max-2 | I5: Fun Tuned | J5: Fun Max | K5: Alt Tuned | L5: Alt Max | M5: FINAL PICK | N5: Final card | O5: Price | P5: Why this card moved
A6: 1 | B6: Felothar the Steadfast | C6: Betor, Kin to All | D6: Betor, Kin to All | E6: Betor, Kin to All | F6: Phyrexian Arena | G6: Phyrexian Arena | H6: Phyrexian Arena | I6: Cloud's Limit Break | J6: Collective Resistance | K6: Teneb, the Harvester | L6: Teneb, the Harvester | M6: Fun Max | N6: =INDEX(B6:L6,MATCH(M6,$B$5:$L$5,0)) | O6: =IFERROR(VLOOKUP(N6,Prices!$A:$B,2,FALSE),0) | P6: =IFERROR(INDEX('_why_1o'!$B2:$L2,MATCH(M6,$B$5:$L$5,0)),"")
A7: 2 | B7: Betor, Ancestor's Voice | C7: Betor, Ancestor's Voice | D7: Betor, Ancestor's Voice | E7: Betor, Ancestor's Voice | F7: Betor, Ancestor's Voice | G7: Betor, Ancestor's Voice | H7: Betor, Ancestor's Voice | I7: Betor, Ancestor's Voice | J7: Betor, Ancestor's Voice | K7: Cloud's Limit Break | L7: Zombie Master | M7: Fun Max | N7: =INDEX(B7:L7,MATCH(M7,$B$5:$L$5,0)) | O7: =IFERROR(VLOOKUP(N7,Prices!$A:$B,2,FALSE),0) | P7: =IFERROR(INDEX('_why_1o'!$B3:$L3,MATCH(M7,$B$5:$L$5,0)),"")
A8: 3 | B8: Protector of the Wastes | C8: Protector of the Wastes | D8: Protector of the Wastes | E8: Protector of the Wastes | F8: Protector of the Wastes | G8: Protector of the Wastes | H8: Protector of the Wastes | I8: Protector of the Wastes | J8: Protector of the Wastes | K8: Protector of the Wastes | L8: Protector of the Wastes | M8: Fun Max | N8: =INDEX(B8:L8,MATCH(M8,$B$5:$L$5,0)) | O8: =IFERROR(VLOOKUP(N8,Prices!$A:$B,2,FALSE),0) | P8: =IFERROR(INDEX('_why_1o'!$B4:$L4,MATCH(M8,$B$5:$L$5,0)),"")
A9: 4 | B9: Reunion of the House | C9: Reunion of the House | D9: Reunion of the House | E9: Reunion of the House | F9: Reunion of the House | G9: Reunion of the House | H9: Reunion of the House | I9: Reunion of the House | J9: Golgari Charm | K9: Reunion of the House | L9: Cloud's Limit Break | M9: Fun Max | N9: =INDEX(B9:L9,MATCH(M9,$B$5:$L$5,0)) | O9: =IFERROR(VLOOKUP(N9,Prices!$A:$B,2,FALSE),0) | P9: =IFERROR(INDEX('_why_1o'!$B5:$L5,MATCH(M9,$B$5:$L$5,0)),"")
A10: 5 | B10: Jaws of Defeat | C10: Ozolith, the Shattered Spire | D10: Ozolith, the Shattered Spire | E10: Ozolith, the Shattered Spire | F10: Authority of the Consuls | G10: Authority of the Consuls | H10: Authority of the Consuls | I10: Valorous Stance | J10: Venat, Heart of Hydaelyn // Hydaelyn, the Mothercrystal | K10: Valorous Stance | L10: Giant's Boulder | M10: Fun Max | N10: =INDEX(B10:L10,MATCH(M10,$B$5:$L$5,0)) | O10: =IFERROR(VLOOKUP(N10,Prices!$A:$B,2,FALSE),0) | P10: =IFERROR(INDEX('_why_1o'!$B6:$L6,MATCH(M10,$B$5:$L$5,0)),"")
A11: 6 | B11: Tip the Scales | C11: Tip the Scales | D11: Hardened Scales | E11: Soul Warden | F11: Zodiark, Umbral God | G11: Zodiark, Umbral God | H11: Zodiark, Umbral God | I11: Golgari Charm | J11: Origin of Metalbending | K11: Golgari Charm | L11: Venat, Heart of Hydaelyn // Hydaelyn, the Mothercrystal | M11: Fun Max | N11: =INDEX(B11:L11,MATCH(M11,$B$5:$L$5,0)) | O11: =IFERROR(VLOOKUP(N11,Prices!$A:$B,2,FALSE),0) | P11: =IFERROR(INDEX('_why_1o'!$B7:$L7,MATCH(M11,$B$5:$L$5,0)),"")
A12: 7 | B12: Will of the Abzan | C12: Will of the Abzan | D12: Will of the Abzan | E12: Will of the Abzan | F12: Valorous Stance | G12: Valorous Stance | H12: Valorous Stance | I12: Golgari Grave-Troll | J12: Will of the Abzan | K12: Golgari Grave-Troll | L12: Will of the Abzan | M12: Fun Max | N12: =INDEX(B12:L12,MATCH(M12,$B$5:$L$5,0)) | O12: =IFERROR(VLOOKUP(N12,Prices!$A:$B,2,FALSE),0) | P12: =IFERROR(INDEX('_why_1o'!$B8:$L8,MATCH(M12,$B$5:$L$5,0)),"")
A13: 8 | B13: Arbor Adherent | C13: Arbor Adherent | D13: Well of Lost Dreams | E13: Arbor Adherent | F13: Blood Artist | G13: Blood Artist | H13: Blood Artist | I13: Arbor Adherent | J13: Snuff Out | K13: Arbor Adherent | L13: Abrupt Decay | M13: Fun Max | N13: =INDEX(B13:L13,MATCH(M13,$B$5:$L$5,0)) | O13: =IFERROR(VLOOKUP(N13,Prices!$A:$B,2,FALSE),0) | P13: =IFERROR(INDEX('_why_1o'!$B9:$L9,MATCH(M13,$B$5:$L$5,0)),"")
A14: 9 | B14: Canopy Gargantuan | C14: Canopy Gargantuan | D14: Canopy Gargantuan | E14: Canopy Gargantuan | F14: Canopy Gargantuan | G14: Canopy Gargantuan | H14: Canopy Gargantuan | I14: Canopy Gargantuan | J14: Canopy Gargantuan | K14: Canopy Gargantuan | L14: Canopy Gargantuan | M14: Fun Max | N14: =INDEX(B14:L14,MATCH(M14,$B$5:$L$5,0)) | O14: =IFERROR(VLOOKUP(N14,Prices!$A:$B,2,FALSE),0) | P14: =IFERROR(INDEX('_why_1o'!$B10:$L10,MATCH(M14,$B$5:$L$5,0)),"")
A15: 10 | B15: Rampart Architect | C15: Rampart Architect | D15: Rampart Architect | E15: Rampart Architect | F15: Rampart Architect | G15: Rampart Architect | H15: Rampart Architect | I15: Rampart Architect | J15: Rampart Architect | K15: Rampart Architect | L15: Rampart Architect | M15: Fun Max | N15: =INDEX(B15:L15,MATCH(M15,$B$5:$L$5,0)) | O15: =IFERROR(VLOOKUP(N15,Prices!$A:$B,2,FALSE),0) | P15: =IFERROR(INDEX('_why_1o'!$B11:$L11,MATCH(M15,$B$5:$L$5,0)),"")
A16: 11 | B16: Tree of Redemption | C16: Tree of Redemption | D16: Tree of Redemption | E16: Tree of Redemption | F16: Tree of Redemption | G16: Tree of Redemption | H16: Tree of Redemption | I16: Tree of Redemption | J16: Tree of Redemption | K16: Tree of Redemption | L16: Tree of Redemption | M16: Fun Max | N16: =INDEX(B16:L16,MATCH(M16,$B$5:$L$5,0)) | O16: =IFERROR(VLOOKUP(N16,Prices!$A:$B,2,FALSE),0) | P16: =IFERROR(INDEX('_why_1o'!$B12:$L12,MATCH(M16,$B$5:$L$5,0)),"")
A17: 12 | B17: Ikra Shidiqi, the Usurper | C17: Hardened Scales | D17: Inspiring Call | E17: Authority of the Consuls | F17: Soul Warden | G17: Soul Warden | H17: Soul Warden | I17: Origin of Metalbending | J17: Damn | K17: Origin of Metalbending | L17: Valorous Stance | M17: Fun Max | N17: =INDEX(B17:L17,MATCH(M17,$B$5:$L$5,0)) | O17: =IFERROR(VLOOKUP(N17,Prices!$A:$B,2,FALSE),0) | P17: =IFERROR(INDEX('_why_1o'!$B13:$L13,MATCH(M17,$B$5:$L$5,0)),"")
... A105: 100 | B105: Forest | C105: Forest | D105: Forest | E105: Forest | F105: Forest | G105: Forest | H105: Forest | I105: Forest | J105: Forest | K105: Forest | L105: Forest | M105: Fun Max | N105: =INDEX(B105:L105,MATCH(M105,$B$5:$L$5,0)) | O105: =IFERROR(VLOOKUP(N105,Prices!$A:$B,2,FALSE),0) | P105: =IFERROR(INDEX('_why_1o'!$B101:$L101,MATCH(M105,$B$5:$L$5,0)),"")
A106: TOTALS | B106: 81.46 | C106: 102.52 | D106: 107.46 | E106: 239.81 | F106: 92.25 | G106: 153.11 | H106: 217.82 | I106: 82.7 | J106: 255.46 | K106: 80.12 | L106: 177.34 | N106: Your selection → | O106: =SUM(O6:O105)
A108: Every row defaults to Fun Max — the newest engine, the full ceiling, and the same commander you already chose. It is a starting point, not a recommendation: change any row. Adopting an Alt column is a commander swap, so it is deliberately never the default; read the Summary tab's alternative-commander block first. Card totals are the full retail value of every card in that column, not what you still need to buy. Amber text marks a card that differs from Base.

Sheet _why_1o
B1: Base | C1: Tuned | D1: Enhance | E1: Max | F1: Tuned-2 | G1: Enhance-2 | H1: Max-2 | I1: Fun Tuned | J1: Fun Max | K1: Alt Tuned | L1: Alt Max
A2: 1 | I2: Replaces Tip the Scales (adds removal/wipe). Evidence: the card it replaces was cast in 56% of the games it was drawn; sat dead in hand 44% of the time; landed on turn 7.1 on average; the deck won 13% of games it was cast in. | J2: Replaces Reunion of the House (adds removal/protection). Evidence: the card it replaces was cast in 64% of the games it was drawn; sat dead in hand 36% of the time; landed on turn 9.1 on average; the deck won 50% of games it was cast in.
A3: 2 | K3: Replaces Tip the Scales (adds removal/wipe). Evidence: the card it replaces was cast in 58% of the games it was drawn; sat dead in hand 42% of the time; landed on turn 6.8 on average; the deck won 17% of games it was cast in. | L3: Replaces Reunion of the House (adds protection/threat). Evidence: the card it replaces was cast in 62% of the games it was drawn; sat dead in hand 38% of the time; landed on turn 9.0 on average; the deck won 54% of games it was cast in.
A4: 3
A5: 4 | J5: Replaces Expel the Interlopers (adds removal/wipe/protection). Evidence: the card it replaces was cast in 54% of the games it was drawn; sat dead in hand 46% of the time; landed on turn 7.9 on average; the deck won 16% of games it was cast in. | L5: Replaces Expel the Interlopers (adds removal/wipe). Evidence: the card it replaces was cast in 56% of the games it was drawn; sat dead in hand 44% of the time; landed on turn 7.5 on average; the deck won 16% of games it was cast in.
A6: 5 | I6: Replaces Will of the Abzan (adds removal/protection). Evidence: the card it replaces was cast in 81% of the games it was drawn; sat dead in hand 19% of the time; landed on turn 8.0 on average; the deck won 46% of games it was cast in. | J6: Replaces Exotic Orchard (adds draw/removal/protection/threat). Evidence: the land it replaces carried no spell effect the model could use; it was drawn in 19% of games; the deck stayed inside its land floor after the cut. | K6: Replaces Will of the Abzan (adds removal/protection). Evidence: the card it replaces was cast in 83% of the games it was drawn; sat dead in hand 17% of the time; landed on turn 7.9 on average; the deck won 47% of games it was cast in. | L6: Replaces Exotic Orchard (adds ramp/removal). Evidence: the land it replaces carried no spell effect the model could use; it was drawn in 19% of games; the deck stayed inside its land floor after the cut.
A7: 6 | F7: Replaces Tip the Scales (adds wipe/protection/finisher/threat). Evidence: the card it replaces was cast in 88% of the games it was drawn; sat dead in hand 12% of the time; landed on turn 6.6 on average; the deck won 14% of games it was cast in. | I7: Replaces Expel the Interlopers (adds removal/wipe/protection). Evidence: the card it replaces was cast in 54% of the games it was drawn; sat dead in hand 46% of the time; landed on turn 7.8 on average; the deck won 13% of games it was cast in. | J7: Replaces Temple of Plenty (adds removal/protection). Evidence: the land it replaces carried no spell effect the model could use; it was drawn in 19% of games; the deck stayed inside its land floor after the cut. | K7: Replaces Expel the Interlopers (adds removal/wipe/protection). Evidence: the card it replaces was cast in 53% of the games it was drawn; sat dead in hand 47% of the time; landed on turn 7.4 on average; the deck won 17% of games it was cast in. | L7: Replaces Wakestone Gargoyle (adds draw/removal/protection/threat). Evidence: the card it replaces was cast in 88% of the games it was drawn; sat dead in hand 12% of the time; landed on turn 7.5 on average; the deck won 51% of games it was cast in.
A8: 7 | F8: Replaces Will of the Abzan (adds removal/protection). Evidence: the card it replaces was cast in 86% of the games it was drawn; sat dead in hand 14% of the time; landed on turn 8.4 on average; the deck won 40% of games it was cast in. | I8: Mandatory legality fix — Tier 2 does not allow Seedborn Muse to stay in this list. | K8: Mandatory legality fix — Tier 2 does not allow Seedborn Muse to stay in this list.
A9: 8 | J9: Replaces Woodland Cemetery (adds removal/protection). Evidence: the land it replaces carried no spell effect the model could use; it was drawn in 19% of games; the deck stayed inside its land floor after the cut. | L9: Replaces Temple of Plenty (adds removal/protection). Evidence: the land it replaces carried no spell effect the model could use; it was drawn in 19% of games; the deck stayed inside its land floor after the cut.
A10: 9
A11: 10
A12: 11
A13: 12 | I13: Replaces Dragonlord Dromoka (adds removal/protection). Evidence: the card it replaces was cast in 89% of the games it was drawn; sat dead in hand 11% of the time; landed on turn 8.1 on average; the deck won 49% of games it was cast in. | J13: Replaces Command Tower (adds removal/protection). Evidence: the land it replaces carried no spell effect the model could use; it was drawn in 19% of games; the deck stayed inside its land floor after the cut. | K13: Replaces Dragonlord Dromoka (adds removal/protection). Evidence: the card it replaces was cast in 87% of the games it was drawn; sat dead in hand 13% of the time; landed on turn 8.3 on average; the deck won 49% of games it was cast in. | L13: Replaces Woodland Cemetery (adds removal/protection). Evidence: the land it replaces carried no spell effect the model could use; it was drawn in 19% of games; the deck stayed inside its land floor after the cut.
A14: 13
A15: 14 | F15: Replaces Expel the Interlopers (adds removal/wipe/protection). Evidence: the card it replaces was cast in 83% of the games it was drawn; sat dead in hand 17% of the time; landed on turn 8.0 on average; the deck won 14% of games it was cast in. | J15: Replaces Path of Ancestry (adds removal/protection). Evidence: the land it replaces carried no spell effect the model could use; it was drawn in 20% of games; the deck stayed inside its land floor after the cut. | L15: Replaces Evolving Wilds (adds removal/protection). Evidence: the land it replaces carried no spell effect the model could use; it was drawn in 19% of games; the deck stayed inside its land floor after the cut.
A16: 15
A17: 16
A18: 17
A19: 18 | F19: Replaces Wakestone Gargoyle (adds draw/removal/protection/threat). Evidence: the card it replaces was cast in 90% of the games it was drawn; sat dead in hand 10% of the time; landed on turn 8.0 on average; the deck won 41% of games it was cast in. | L19: Replaces Path of Ancestry (adds removal/protection/finisher/threat). Evidence: the land it replaces carried no spell effect the model could use; it was drawn in 20% of games; the deck stayed inside its land floor after the cut.
A20: 19
A21: 20
A22: 21 | F22: Replaces Zetalpa, Primal Dawn (adds removal/protection). Evidence: the card it replaces was cast in 79% of the games it was drawn; sat dead in hand 21% of the time; landed on turn 9.1 on average; the deck won 42% of games it was cast in.
A23: 22
A24: 23
A25: 24
A26: 25 | F26: Mandatory legality fix — Tier 2 does not allow Seedborn Muse to stay in this list.
A27: 26
A28: 27
A29: 28
A30: 29
A31: 30
A32: 31
A33: 32
A34: 33
A35: 34
A36: 35
A37: 36
A38: 37
... A47: 46
A48: 47 | J48: Replaces Felidar Retreat (adds removal/protection). Evidence: the card it replaces was cast in 81% of the games it was drawn; sat dead in hand 19% of the time; landed on turn 7.9 on average; the deck won 49% of games it was cast in. | L48: Replaces Felidar Retreat (adds removal/protection). Evidence: the card it replaces was cast in 81% of the games it was drawn; sat dead in hand 19% of the time; landed on turn 7.9 on average; the deck won 49% of games it was cast in.
...

Sheet 2c Proliferate Council
A1: Proliferate Council — Atraxa, Praetors' Voice
A2: Deck slot 2 · variant 2c · 100 lineup slots
B4: Site ladder — as published | F4: Simulation-improved (Monte Carlo) | I4: Fun-weighted engine v2.1
A5: Slot | B5: Base | C5: Tuned | D5: Enhance | E5: Max | F5: Tuned-2 | G5: Enhance-2 | H5: Max-2 | I5: Fun Tuned | J5: Fun Max | K5: FINAL PICK | L5: Final card | M5: Price | N5: Why this card moved
A6: 1 | B6: Thrummingbird | C6: Thrummingbird | D6: Thrummingbird | E6: Thrummingbird | F6: Thrummingbird | G6: Thrummingbird | H6: Thrummingbird | I6: Thrummingbird | J6: Thrummingbird | K6: Fun Max | L6: =INDEX(B6:J6,MATCH(K6,$B$5:$J$5,0)) | M6: =IFERROR(VLOOKUP(L6,Prices!$A:$B,2,FALSE),0) | N6: =IFERROR(INDEX('_why_2c'!$B2:$J2,MATCH(K6,$B$5:$J$5,0)),"")
A7: 2 | B7: Viral Drake | C7: Viral Drake | D7: Viral Drake | E7: Viral Drake | F7: Viral Drake | G7: Viral Drake | H7: Viral Drake | I7: Viral Drake | J7: Viral Drake | K7: Fun Max | L7: =INDEX(B7:J7,MATCH(K7,$B$5:$J$5,0)) | M7: =IFERROR(VLOOKUP(L7,Prices!$A:$B,2,FALSE),0) | N7: =IFERROR(INDEX('_why_2c'!$B3:$J3,MATCH(K7,$B$5:$J$5,0)),"")
A8: 3 | B8: Evolution Sage | C8: Evolution Sage | D8: Evolution Sage | E8: Evolution Sage | F8: Evolution Sage | G8: Evolution Sage | H8: Evolution Sage | I8: Evolution Sage | J8: Evolution Sage | K8: Fun Max | L8: =INDEX(B8:J8,MATCH(K8,$B$5:$J$5,0)) | M8: =IFERROR(VLOOKUP(L8,Prices!$A:$B,2,FALSE),0) | N8: =IFERROR(INDEX('_why_2c'!$B4:$J4,MATCH(K8,$B$5:$J$5,0)),"")
A9: 4 | B9: Contagion Clasp | C9: Contagion Clasp | D9: Contagion Clasp | E9: Contagion Clasp | F9: Contagion Clasp | G9: Contagion Clasp | H9: Contagion Clasp | I9: Contagion Clasp | J9: Contagion Clasp | K9: Fun Max | L9: =INDEX(B9:J9,MATCH(K9,$B$5:$J$5,0)) | M9: =IFERROR(VLOOKUP(L9,Prices!$A:$B,2,FALSE),0) | N9: =IFERROR(INDEX('_why_2c'!$B5:$J5,MATCH(K9,$B$5:$J$5,0)),"")
A10: 5 | B10: Steady Progress | C10: Steady Progress | D10: Steady Progress | E10: Steady Progress | F10: Steady Progress | G10: Steady Progress | H10: Steady Progress | I10: Steady Progress | J10: Steady Progress | K10: Fun Max | L10: =INDEX(B10:J10,MATCH(K10,$B$5:$J$5,0)) | M10: =IFERROR(VLOOKUP(L10,Prices!$A:$B,2,FALSE),0) | N10: =IFERROR(INDEX('_why_2c'!$B6:$J6,MATCH(K10,$B$5:$J$5,0)),"")
A11: 6 | B11: Tezzeret's Gambit | C11: Tezzeret's Gambit | D11: Tezzeret's Gambit | E11: Tezzeret's Gambit | F11: Tezzeret's Gambit | G11: Tezzeret's Gambit | H11: Tezzeret's Gambit | I11: Tezzeret's Gambit | J11: Tezzeret's Gambit | K11: Fun Max | L11: =INDEX(B11:J11,MATCH(K11,$B$5:$J$5,0)) | M11: =IFERROR(VLOOKUP(L11,Prices!$A:$B,2,FALSE),0) | N11: =IFERROR(INDEX('_why_2c'!$B7:$J7,MATCH(K11,$B$5:$J$5,0)),"")
A12: 7 | B12: Grim Affliction | C12: Grim Affliction | D12: Grim Affliction | E12: Grim Affliction | F12: Grim Affliction | G12: Grim Affliction | H12: Grim Affliction | I12: Grim Affliction | J12: Grim Affliction | K12: Fun Max | L12: =INDEX(B12:J12,MATCH(K12,$B$5:$J$5,0)) | M12: =IFERROR(VLOOKUP(L12,Prices!$A:$B,2,FALSE),0) | N12: =IFERROR(INDEX('_why_2c'!$B8:$J8,MATCH(K12,$B$5:$J$5,0)),"")
A13: 8 | B13: Throne of Geth | C13: Throne of Geth | D13: Throne of Geth | E13: Throne of Geth | F13: Throne of Geth | G13: Throne of Geth | H13: Throne of Geth | I13: Throne of Geth | J13: Throne of Geth | K13: Fun Max | L13: =INDEX(B13:J13,MATCH(K13,$B$5:$J$5,0)) | M13: =IFERROR(VLOOKUP(L13,Prices!$A:$B,2,FALSE),0) | N13: =IFERROR(INDEX('_why_2c'!$B9:$J9,MATCH(K13,$B$5:$J$5,0)),"")
A14: 9 | B14: Conclave Mentor | C14: Conclave Mentor | D14: Conclave Mentor | E14: Teferi's Protection | F14: Conclave Mentor | G14: Doubling Season | H14: Doubling Season | I14: Conclave Mentor | J14: Portcullis Vine | K14: Fun Max | L14: =INDEX(B14:J14,MATCH(K14,$B$5:$J$5,0)) | M14: =IFERROR(VLOOKUP(L14,Prices!$A:$B,2,FALSE),0) | N14: =IFERROR(INDEX('_why_2c'!$B10:$J10,MATCH(K14,$B$5:$J$5,0)),"")
A15: 10 | B15: Corpsejack Menace | C15: Corpsejack Menace | D15: Corpsejack Menace | E15: Corpsejack Menace | F15: Corpsejack Menace | G15: Corpsejack Menace | H15: Corpsejack Menace | I15: Corpsejack Menace | J15: Corpsejack Menace | K15: Fun Max | L15: =INDEX(B15:J15,MATCH(K15,$B$5:$J$5,0)) | M15: =IFERROR(VLOOKUP(L15,Prices!$A:$B,2,FALSE),0) | N15: =IFERROR(INDEX('_why_2c'!$B11:$J11,MATCH(K15,$B$5:$J$5,0)),"")
A16: 11 | B16: Vorel of the Hull Clade | C16: Vorel of the Hull Clade | D16: Vorel of the Hull Clade | E16: Vorel of the Hull Clade | F16: Vorel of the Hull Clade | G16: Vorel of the Hull Clade | H16: Vorel of the Hull Clade | I16: Vorel of the Hull Clade | J16: Vorel of the Hull Clade | K16: Fun Max | L16: =INDEX(B16:J16,MATCH(K16,$B$5:$J$5,0)) | M16: =IFERROR(VLOOKUP(L16,Prices!$A:$B,2,FALSE),0) | N16: =IFERROR(INDEX('_why_2c'!$B12:$J12,MATCH(K16,$B$5:$J$5,0)),"")
A17: 12 | B17: Forgotten Ancient | C17: Forgotten Ancient | D17: Forgotten Ancient | E17: Forgotten Ancient | F17: Forgotten Ancient | G17: Forgotten Ancient | H17: Forgotten Ancient | I17: Forgotten Ancient | J17: Forgotten Ancient | K17: Fun Max | L17: =INDEX(B17:J17,MATCH(K17,$B$5:$J$5,0)) | M17: =IFERROR(VLOOKUP(L17,Prices!$A:$B,2,FALSE),0) | N17: =IFERROR(INDEX('_why_2c'!$B13:$J13,MATCH(K17,$B$5:$J$5,0)),"")
... A105: 100 | B105: The Ozolith | C105: The Ozolith | D105: The Ozolith | E105: The Ozolith | F105: The Ozolith | G105: The Ozolith | H105: The Ozolith | I105: The Ozolith | J105: The Ozolith | K105: Fun Max | L105: =INDEX(B105:J105,MATCH(K105,$B$5:$J$5,0)) | M105: =IFERROR(VLOOKUP(L105,Prices!$A:$B,2,FALSE),0) | N105: =IFERROR(INDEX('_why_2c'!$B101:$J101,MATCH(K105,$B$5:$J$5,0)),"")
A106: TOTALS | B106: 158.43 | C106: 167.25 | D106: 166.24 | E106: 401.89 | F106: 181.97 | G106: 346.92 | H106: 346.92 | I106: 168.86 | J106: 403.57 | L106: Your selection → | M106: =SUM(M6:M105)
A108: Every row defaults to Fun Max — the newest engine, the full ceiling, and the same commander you already chose. It is a starting point, not a recommendation: change any row. Adopting an Alt column is a commander swap, so it is deliberately never the default; read the Summary tab's alternative-commander block first. Card totals are the full retail value of every card in that column, not what you still need to buy. Amber text marks a card that differs from Base.

Sheet _why_2c
B1: Base | C1: Tuned | D1: Enhance | E1: Max | F1: Tuned-2 | G1: Enhance-2 | H1: Max-2 | I1: Fun Tuned | J1: Fun Max
A2: 1
A3: 2
A4: 3
A5: 4
A6: 5
A7: 6
A8: 7
A9: 8
A10: 9 | J10: Replaces Esper Panorama (adds draw/threat). Evidence: the land it replaces carried no spell effect the model could use; it was drawn in 21% of games; the deck stayed inside its land floor after the cut.
A11: 10
A12: 11
A13: 12
A14: 13
A15: 14
A16: 15
A17: 16
A18: 17
A19: 18
A20: 19 | I20: Replaces Command Tower (adds draw/finisher/threat). Evidence: the land it replaces carried no spell effect the model could use; it was drawn in 21% of games; the deck stayed inside its land floor after the cut. | J20: Replaces Terramorphic Expanse (adds draw/threat). Evidence: the land it replaces carried no spell effect the model could use; it was drawn in 20% of games; the deck stayed inside its land floor after the cut.
A21: 20
A22: 21
A23: 22
A24: 23 | J24: Replaces Scoured Barrens (adds draw/finisher/threat). Evidence: the land it replaces carried no spell effect the model could use; it was drawn in 21% of games; the deck stayed inside its land floor after the cut.
A25: 24
A26: 25
A27: 26
A28: 27
A29: 28
A30: 29
A31: 30 | F31: Replaces Putrefy (adds removal/finisher/threat). Evidence: the card it replaces was cast in 89% of the games it was drawn; sat dead in hand 11% of the time; landed on turn 8.2 on average; the deck won 28% of games it was cast in.
A32: 31
A33: 32 | F33: Replaces Utter End (adds finisher/threat). Evidence: the card it replaces was cast in 92% of the games it was drawn; sat dead in hand 8% of the time; landed on turn 8.7 on average; the deck won 26% of games it was cast in.
A34: 33 | J34: Replaces Orzhov Basilica (adds draw/threat). Evidence: the land it replaces carried no spell effect the model could use; it was drawn in 22% of games; the deck stayed inside its land floor after the cut.
A35: 34
A36: 35
A37: 36 | I37: Replaces Sandsteppe Citadel (adds draw/threat). Evidence: the land it replaces carried no spell effect the model could use; it was drawn in 21% of games; the deck stayed inside its land floor after the cut. | J37: Replaces Sunpetal Grove (adds draw/threat). Evidence: the land it replaces carried no spell effect the model could use; it was drawn in 22% of games; the deck stayed inside its land floor after the cut.
A38: 37
A39: 38 | F39: Replaces Fact or Fiction (adds threat). Evidence: the card it replaces was cast in 92% of the games it was drawn; sat dead in hand 8% of the time; landed on turn 8.3 on average; the deck won 25% of games it was cast in.
A40: 39
...

Sheet 3e Golgari Land Engine
A1: Golgari Land Engine — The Gitrog Monster
A2: Deck slot 3 · variant 3e · 100 lineup slots · alternative commander tested: Hazel of the Rootbloom
B4: Site ladder — as published | F4: Simulation-improved (Monte Carlo) | I4: Fun-weighted engine v2.1 | K4: Alternative commander
A5: Slot | B5: Base | C5: Tuned | D5: Enhance | E5: Max | F5: Tuned-2 | G5: Enhance-2 | H5: Max-2 | I5: Fun Tuned | J5: Fun Max | K5: Alt Tuned | L5: Alt Max | M5: FINAL PICK | N5: Final card | O5: Price | P5: Why this card moved
A6: 1 | B6: Sakura-Tribe Elder | C6: Sakura-Tribe Elder | D6: Sakura-Tribe Elder | E6: Sakura-Tribe Elder | F6: Sakura-Tribe Elder | G6: Sakura-Tribe Elder | H6: Sakura-Tribe Elder | I6: Sakura-Tribe Elder | J6: Sakura-Tribe Elder | K6: Sakura-Tribe Elder | L6: Sakura-Tribe Elder | M6: Fun Max | N6: =INDEX(B6:L6,MATCH(M6,$B$5:$L$5,0)) | O6: =IFERROR(VLOOKUP(N6,Prices!$A:$B,2,FALSE),0) | P6: =IFERROR(INDEX('_why_3e'!$B2:$L2,MATCH(M6,$B$5:$L$5,0)),"")
A7: 2 | B7: Wood Elves | C7: Wood Elves | D7: Wood Elves | E7: Wood Elves | F7: Wood Elves | G7: Wood Elves | H7: Wood Elves | I7: Wood Elves | J7: Wood Elves | K7: Wood Elves | L7: Wood Elves | M7: Fun Max | N7: =INDEX(B7:L7,MATCH(M7,$B$5:$L$5,0)) | O7: =IFERROR(VLOOKUP(N7,Prices!$A:$B,2,FALSE),0) | P7: =IFERROR(INDEX('_why_3e'!$B3:$L3,MATCH(M7,$B$5:$L$5,0)),"")
A8: 3 | B8: Yavimaya Elder | C8: Yavimaya Elder | D8: Yavimaya Elder | E8: Yavimaya Elder | F8: Yavimaya Elder | G8: Yavimaya Elder | H8: Yavimaya Elder | I8: Yavimaya Elder | J8: Yavimaya Elder | K8: Yavimaya Elder | L8: Yavimaya Elder | M8: Fun Max | N8: =INDEX(B8:L8,MATCH(M8,$B$5:$L$5,0)) | O8: =IFERROR(VLOOKUP(N8,Prices!$A:$B,2,FALSE),0) | P8: =IFERROR(INDEX('_why_3e'!$B4:$L4,MATCH(M8,$B$5:$L$5,0)),"")
A9: 4 | B9: Solemn Simulacrum | C9: Solemn Simulacrum | D9: Solemn Simulacrum | E9: Solemn Simulacrum | F9: Solemn Simulacrum | G9: Solemn Simulacrum | H9: Solemn Simulacrum | I9: Solemn Simulacrum | J9: Solemn Simulacrum | K9: Solemn Simulacrum | L9: Solemn Simulacrum | M9: Fun Max | N9: =INDEX(B9:L9,MATCH(M9,$B$5:$L$5,0)) | O9: =IFERROR(VLOOKUP(N9,Prices!$A:$B,2,FALSE),0) | P9: =IFERROR(INDEX('_why_3e'!$B5:$L5,MATCH(M9,$B$5:$L$5,0)),"")
A10: 5 | B10: Sylvan Ranger | C10: Sylvan Ranger | D10: Sylvan Ranger | E10: Sylvan Ranger | F10: Sylvan Ranger | G10: Sylvan Ranger | H10: Sylvan Ranger | I10: Sylvan Ranger | J10: Sylvan Ranger | K10: Sylvan Ranger | L10: Sylvan Ranger | M10: Fun Max | N10: =INDEX(B10:L10,MATCH(M10,$B$5:$L$5,0)) | O10: =IFERROR(VLOOKUP(N10,Prices!$A:$B,2,FALSE),0) | P10: =IFERROR(INDEX('_why_3e'!$B6:$L6,MATCH(M10,$B$5:$L$5,0)),"")
A11: 6 | B11: Tireless Tracker | C11: Tireless Tracker | D11: Tireless Tracker | E11: Tireless Tracker | F11: Tireless Tracker | G11: Tireless Tracker | H11: Tireless Tracker | I11: Tireless Tracker | J11: Tireless Tracker | K11: Tireless Tracker | L11: Tireless Tracker | M11: Fun Max | N11: =INDEX(B11:L11,MATCH(M11,$B$5:$L$5,0)) | O11: =IFERROR(VLOOKUP(N11,Prices!$A:$B,2,FALSE),0) | P11: =IFERROR(INDEX('_why_3e'!$B7:$L7,MATCH(M11,$B$5:$L$5,0)),"")
A12: 7 | B12: Perpetual Timepiece | C12: Perpetual Timepiece | D12: Perpetual Timepiece | E12: Perpetual Timepiece | F12: Perpetual Timepiece | G12: Perpetual Timepiece | H12: Perpetual Timepiece | I12: Perpetual Timepiece | J12: Perpetual Timepiece | K12: Perpetual Timepiece | L12: Perpetual Timepiece | M12: Fun Max | N12: =INDEX(B12:L12,MATCH(M12,$B$5:$L$5,0)) | O12: =IFERROR(VLOOKUP(N12,Prices!$A:$B,2,FALSE),0) | P12: =IFERROR(INDEX('_why_3e'!$B8:$L8,MATCH(M12,$B$5:$L$5,0)),"")
A13: 8 | B13: Sol Ring | C13: Sol Ring | D13: Sol Ring | E13: Sol Ring | F13: Sol Ring | G13: Sol Ring | H13: Sol Ring | I13: Sol Ring | J13: Sol Ring | K13: Sol Ring | L13: Sol Ring | M13: Fun Max | N13: =INDEX(B13:L13,MATCH(M13,$B$5:$L$5,0)) | O13: =IFERROR(VLOOKUP(N13,Prices!$A:$B,2,FALSE),0) | P13: =IFERROR(INDEX('_why_3e'!$B9:$L9,MATCH(M13,$B$5:$L$5,0)),"")
A14: 9 | B14: Arcane Signet | C14: Ramunap Excavator | D14: Ramunap Excavator | E14: Field of the Dead | F14: Ramunap Excavator | G14: Crucible of Worlds | H14: Crucible of Worlds | I14: Inspiring Call | J14: Heritage Reclamation | K14: Heritage Reclamation | L14: Snuff Out | M14: Fun Max | N14: =INDEX(B14:L14,MATCH(M14,$B$5:$L$5,0)) | O14: =IFERROR(VLOOKUP(N14,Prices!$A:$B,2,FALSE),0) | P14: =IFERROR(INDEX('_why_3e'!$B10:$L10,MATCH(M14,$B$5:$L$5,0)),"")
A15: 10 | B15: Golgari Signet | C15: Golgari Signet | D15: Golgari Signet | E15: Golgari Signet | F15: Golgari Signet | G15: Golgari Signet | H15: Golgari Signet | I15: Golgari Signet | J15: Golgari Signet | K15: Golgari Signet | L15: Golgari Signet | M15: Fun Max | N15: =INDEX(B15:L15,MATCH(M15,$B$5:$L$5,0)) | O15: =IFERROR(VLOOKUP(N15,Prices!$A:$B,2,FALSE),0) | P15: =IFERROR(INDEX('_why_3e'!$B11:$L11,MATCH(M15,$B$5:$L$5,0)),"")
A16: 11 | B16: Harrow | C16: Harrow | D16: Harrow | E16: Harrow | F16: Harrow | G16: Harrow | H16: Harrow | I16: Harrow | J16: Harrow | K16: Harrow | L16: Harrow | M16: Fun Max | N16: =INDEX(B16:L16,MATCH(M16,$B$5:$L$5,0)) | O16: =IFERROR(VLOOKUP(N16,Prices!$A:$B,2,FALSE),0) | P16: =IFERROR(INDEX('_why_3e'!$B12:$L12,MATCH(M16,$B$5:$L$5,0)),"")
A17: 12 | B17: Cultivate | C17: Cultivate | D17: Cultivate | E17: Cultivate | F17: Cultivate | G17: Cultivate | H17: Cultivate | I17: Cultivate | J17: Cultivate | K17: Cultivate | L17: Cultivate | M17: Fun Max | N17: =INDEX(B17:L17,MATCH(M17,$B$5:$L$5,0)) | O17: =IFERROR(VLOOKUP(N17,Prices!$A:$B,2,FALSE),0) | P17: =IFERROR(INDEX('_why_3e'!$B13:$L13,MATCH(M17,$B$5:$L$5,0)),"")
... A105: 100 | B105: Currency Converter | C105: Currency Converter | D105: Currency Converter | E105: Currency Converter | F105: Currency Converter | G105: Currency Converter | H105: Currency Converter | I105: Currency Converter | J105: Currency Converter | K105: Currency Converter | L105: Currency Converter | M105: Fun Max | N105: =INDEX(B105:L105,MATCH(M105,$B$5:$L$5,0)) | O105: =IFERROR(VLOOKUP(N105,Prices!$A:$B,2,FALSE),0) | P105: =IFERROR(INDEX('_why_3e'!$B101:$L101,MATCH(M105,$B$5:$L$5,0)),"")
A106: TOTALS | B106: 54.81 | C106: 64.41 | D106: 64.3 | E106: 154.99 | F106: 230.36 | G106: 290.78 | H106: 290.78 | I106: 118.97 | J106: 179.51 | K106: 122.96 | L106: 194.4 | N106: Your selection → | O106: =SUM(O6:O105)
A108: Every row defaults to Fun Max — the newest engine, the full ceiling, and the same commander you already chose. It is a starting point, not a recommendation: change any row. Adopting an Alt column is a commander swap, so it is deliberately never the default; read the Summary tab's alternative-commander block first. Card totals are the full retail value of every card in that column, not what you still need to buy. Amber text marks a card that differs from Base.

Sheet _why_3e
B1: Base | C1: Tuned | D1: Enhance | E1: Max | F1: Tuned-2 | G1: Enhance-2 | H1: Max-2 | I1: Fun Tuned | J1: Fun Max | K1: Alt Tuned | L1: Alt Max
A2: 1
A3: 2
A4: 3
A5: 4
A6: 5
A7: 6
A8: 7
A9: 8
A10: 9 | I10: Replaces Blighted Woodland (adds draw/protection). Evidence: the land it replaces carried no spell effect the model could use; it was drawn in 18% of games; the deck stayed inside its land floor after the cut. | J10: Replaces Command Tower (adds draw/removal). Evidence: the land it replaces carried no spell effect the model could use; it was drawn in 18% of games; the deck stayed inside its land floor after the cut. | K10: Replaces Llanowar Wastes (adds draw/removal). Evidence: the land it replaces carried no spell effect the model could use; it was drawn in 19% of games; the deck stayed inside its land floor after the cut. | L10: Replaces Casualties of War (adds removal/protection). Evidence: the card it replaces was cast in 96% of the games it was drawn; sat dead in hand 4% of the time; landed on turn 7.5 on average; the deck won 35% of games it was cast in.
A11: 10
A12: 11
A13: 12
A14: 13
A15: 14
A16: 15
A17: 16
A18: 17
A19: 18
A20: 19
A21: 20
A22: 21
A23: 22 | I23: Replaces Llanowar Wastes (adds draw/removal/threat). Evidence: the land it replaces carried no spell effect the model could use; it was drawn in 19% of games; the deck stayed inside its land floor after the cut. | J23: Replaces Woodland Cemetery (adds draw/protection). Evidence: the land it replaces carried no spell effect the model could use; it was drawn in 17% of games; the deck stayed inside its land floor after the cut. | K23: Replaces Golgari Rot Farm (adds draw/protection). Evidence: the land it replaces carried no spell effect the model could use; it was drawn in 19% of games; the deck stayed inside its land floor after the cut. | L23: Replaces Command Tower (adds draw/removal). Evidence: the land it replaces carried no spell effect the model could use; it was drawn in 18% of games; the deck stayed inside its land floor after the cut.
A24: 23 | I24: Replaces Golgari Rot Farm (adds removal/protection). Evidence: the land it replaces carried no spell effect the model could use; it was drawn in 20% of games; the deck stayed inside its land floor after the cut. | J24: Replaces Bojuka Bog (adds draw/removal). Evidence: the land it replaces carried no spell effect the model could use; it was drawn in 19% of games; the deck stayed inside its land floor after the cut. | K24: Replaces Bojuka Bog (adds removal/protection). Evidence: the land it replaces carried no spell effect the model could use; it was drawn in 20% of games; the deck stayed inside its land floor after the cut. | L24: Replaces Woodland Cemetery (adds removal/protection). Evidence: the land it replaces carried no spell effect the model could use; it was drawn in 17% of games; the deck stayed inside its land floor after the cut.
A25: 24
A26: 25 | F26: Replaces Casualties of War (adds removal/protection). Evidence: the card it replaces was cast in 93% of the games it was drawn; sat dead in hand 7% of the time; landed on turn 8.0 on average; the deck won 37% of games it was cast in. | L26: Replaces Bojuka Bog (adds draw/removal). Evidence: the land it replaces carried no spell effect the model could use; it was drawn in 19% of games; the deck stayed inside its land floor after the cut.
A27: 26
A28: 27
A29: 28
A30: 29
A31: 30
A32: 31
A33: 32
A34: 33
A35: 34
A36: 35
A37: 36
A38: 37 | I38: Replaces Bojuka Bog (adds removal/protection). Evidence: the land it replaces carried no spell effect the model could use; it was drawn in 20% of games; the deck stayed inside its land floor after the cut.
A39: 38
A40: 39
...

Sheet 4c Bant Walls
A1: Bant Walls — Arcades, the Strategist
A2: Deck slot 4 · variant 4c · 100 lineup slots
B4: Site ladder — as published | F4: Simulation-improved (Monte Carlo) | I4: Fun-weighted engine v2.1
A5: Slot | B5: Base | C5: Tuned | D5: Enhance | E5: Max | F5: Tuned-2 | G5: Enhance-2 | H5: Max-2 | I5: Fun Tuned | J5: Fun Max | K5: FINAL PICK | L5: Final card | M5: Price | N5: Why this card moved
A6: 1 | B6: Wall of Denial | C6: Wall of Denial | D6: Wall of Denial | E6: Wall of Denial | F6: Wall of Denial | G6: Wall of Denial | H6: Wall of Denial | I6: Wall of Denial | J6: Wall of Denial | K6: Fun Max | L6: =INDEX(B6:J6,MATCH(K6,$B$5:$J$5,0)) | M6: =IFERROR(VLOOKUP(L6,Prices!$A:$B,2,FALSE),0) | N6: =IFERROR(INDEX('_why_4c'!$B2:$J2,MATCH(K6,$B$5:$J$5,0)),"")
A7: 2 | B7: Fog Bank | C7: Fog Bank | D7: Fog Bank | E7: Fog Bank | F7: Fog Bank | G7: Fog Bank | H7: Fog Bank | I7: Fog Bank | J7: Fog Bank | K7: Fun Max | L7: =INDEX(B7:J7,MATCH(K7,$B$5:$J$5,0)) | M7: =IFERROR(VLOOKUP(L7,Prices!$A:$B,2,FALSE),0) | N7: =IFERROR(INDEX('_why_4c'!$B3:$J3,MATCH(K7,$B$5:$J$5,0)),"")
A8: 3 | B8: Wall of Junk | C8: Wall of Junk | D8: Wall of Junk | E8: Wall of Junk | F8: Wall of Junk | G8: Wall of Junk | H8: Wall of Junk | I8: Wall of Junk | J8: Wall of Junk | K8: Fun Max | L8: =INDEX(B8:J8,MATCH(K8,$B$5:$J$5,0)) | M8: =IFERROR(VLOOKUP(L8,Prices!$A:$B,2,FALSE),0) | N8: =IFERROR(INDEX('_why_4c'!$B4:$J4,MATCH(K8,$B$5:$J$5,0)),"")
A9: 4 | B9: Perimeter Captain | C9: Perimeter Captain | D9: Perimeter Captain | E9: Perimeter Captain | F9: Perimeter Captain | G9: Perimeter Captain | H9: Perimeter Captain | I9: Perimeter Captain | J9: Perimeter Captain | K9: Fun Max | L9: =INDEX(B9:J9,MATCH(K9,$B$5:$J$5,0)) | M9: =IFERROR(VLOOKUP(L9,Prices!$A:$B,2,FALSE),0) | N9: =IFERROR(INDEX('_why_4c'!$B5:$J5,MATCH(K9,$B$5:$J$5,0)),"")
A10: 5 | B10: Shield Sphere | C10: Shield Sphere | D10: Shield Sphere | E10: Shield Sphere | F10: Shield Sphere | G10: Shield Sphere | H10: Shield Sphere | I10: Shield Sphere | J10: Shield Sphere | K10: Fun Max | L10: =INDEX(B10:J10,MATCH(K10,$B$5:$J$5,0)) | M10: =IFERROR(VLOOKUP(L10,Prices!$A:$B,2,FALSE),0) | N10: =IFERROR(INDEX('_why_4c'!$B6:$J6,MATCH(K10,$B$5:$J$5,0)),"")
A11: 6 | B11: Steel Wall | C11: Steel Wall | D11: Steel Wall | E11: Steel Wall | F11: Steel Wall | G11: Steel Wall | H11: Steel Wall | I11: Steel Wall | J11: Steel Wall | K11: Fun Max | L11: =INDEX(B11:J11,MATCH(K11,$B$5:$J$5,0)) | M11: =IFERROR(VLOOKUP(L11,Prices!$A:$B,2,FALSE),0) | N11: =IFERROR(INDEX('_why_4c'!$B7:$J7,MATCH(K11,$B$5:$J$5,0)),"")
A12: 7 | B12: Wall of Frost | C12: Wall of Frost | D12: Wall of Frost | E12: Wall of Frost | F12: Aesi, Tyrant of Gyre Strait | G12: Aesi, Tyrant of Gyre Strait | H12: Aesi, Tyrant of Gyre Strait | I12: Wall of Frost | J12: Wall of Frost | K12: Fun Max | L12: =INDEX(B12:J12,MATCH(K12,$B$5:$J$5,0)) | M12: =IFERROR(VLOOKUP(L12,Prices!$A:$B,2,FALSE),0) | N12: =IFERROR(INDEX('_why_4c'!$B8:$J8,MATCH(K12,$B$5:$J$5,0)),"")
A13: 8 | B13: Glacial Wall | C13: Glacial Wall | D13: Glacial Wall | E13: Glacial Wall | F13: Kruphix, God of Horizons | G13: Kruphix, God of Horizons | H13: Kruphix, God of Horizons | I13: Glacial Wall | J13: Glacial Wall | K13: Fun Max | L13: =INDEX(B13:J13,MATCH(K13,$B$5:$J$5,0)) | M13: =IFERROR(VLOOKUP(L13,Prices!$A:$B,2,FALSE),0) | N13: =IFERROR(INDEX('_why_4c'!$B9:$J9,MATCH(K13,$B$5:$J$5,0)),"")
A14: 9 | B14: Overgrown Battlement | C14: Overgrown Battlement | D14: Overgrown Battlement | E14: Overgrown Battlement | F14: Overgrown Battlement | G14: Overgrown Battlement | H14: Overgrown Battlement | I14: Overgrown Battlement | J14: Overgrown Battlement | K14: Fun Max | L14: =INDEX(B14:J14,MATCH(K14,$B$5:$J$5,0)) | M14: =IFERROR(VLOOKUP(L14,Prices!$A:$B,2,FALSE),0) | N14: =IFERROR(INDEX('_why_4c'!$B10:$J10,MATCH(K14,$B$5:$J$5,0)),"")
A15: 10 | B15: Vine Trellis | C15: Vine Trellis | D15: Vine Trellis | E15: Vine Trellis | F15: Vine Trellis | G15: Vine Trellis | H15: Vine Trellis | I15: Vine Trellis | J15: Vine Trellis | K15: Fun Max | L15: =INDEX(B15:J15,MATCH(K15,$B$5:$J$5,0)) | M15: =IFERROR(VLOOKUP(L15,Prices!$A:$B,2,FALSE),0) | N15: =IFERROR(INDEX('_why_4c'!$B11:$J11,MATCH(K15,$B$5:$J$5,0)),"")
A16: 11 | B16: Wall of Tanglecord | C16: Wall of Tanglecord | D16: Wall of Tanglecord | E16: Wall of Tanglecord | F16: Wall of Tanglecord | G16: Wall of Tanglecord | H16: Wall of Tanglecord | I16: Wall of Tanglecord | J16: Wall of Tanglecord | K16: Fun Max | L16: =INDEX(B16:J16,MATCH(K16,$B$5:$J$5,0)) | M16: =IFERROR(VLOOKUP(L16,Prices!$A:$B,2,FALSE),0) | N16: =IFERROR(INDEX('_why_4c'!$B12:$J12,MATCH(K16,$B$5:$J$5,0)),"")
A17: 12 | B17: Wall of Kelp | C17: Wall of Kelp | D17: Wall of Kelp | E17: Wall of Kelp | F17: Wall of Kelp | G17: Wall of Kelp | H17: Wall of Kelp | I17: Wall of Kelp | J17: Wall of Kelp | K17: Fun Max | L17: =INDEX(B17:J17,MATCH(K17,$B$5:$J$5,0)) | M17: =IFERROR(VLOOKUP(L17,Prices!$A:$B,2,FALSE),0) | N17: =IFERROR(INDEX('_why_4c'!$B13:$J13,MATCH(K17,$B$5:$J$5,0)),"")
... A105: 100 | B105: Bedrock Tortoise | C105: Bedrock Tortoise | D105: Bedrock Tortoise | E105: Bedrock Tortoise | F105: Bedrock Tortoise | G105: Bedrock Tortoise | H105: Bedrock Tortoise | I105: Bedrock Tortoise | J105: Bedrock Tortoise | K105: Fun Max | L105: =INDEX(B105:J105,MATCH(K105,$B$5:$J$5,0)) | M105: =IFERROR(VLOOKUP(L105,Prices!$A:$B,2,FALSE),0) | N105: =IFERROR(INDEX('_why_4c'!$B101:$J101,MATCH(K105,$B$5:$J$5,0)),"")
A106: TOTALS | B106: 57.94 | C106: 56.28 | D106: 57.29 | E106: 126.51 | F106: 124.43 | G106: 185.34 | H106: 185.34 | I106: 65.66 | J106: 131.47 | L106: Your selection → | M106: =SUM(M6:M105)
A108: Every row defaults to Fun Max — the newest engine, the full ceiling, and the same commander you already chose. It is a starting point, not a recommendation: change any row. Adopting an Alt column is a commander swap, so it is deliberately never the default; read the Summary tab's alternative-commander block first. Card totals are the full retail value of every card in that column, not what you still need to buy. Amber text marks a card that differs from Base.

Sheet _why_4c
B1: Base | C1: Tuned | D1: Enhance | E1: Max | F1: Tuned-2 | G1: Enhance-2 | H1: Max-2 | I1: Fun Tuned | J1: Fun Max
A2: 1
A3: 2
A4: 3
A5: 4
A6: 5
A7: 6
A8: 7
A9: 8 | F9: Replaces Glacial Wall (adds protection/finisher/threat). Evidence: the card it replaces was cast in 90% of the games it was drawn; sat dead in hand 10% of the time; landed on turn 7.5 on average; the deck won 22% of games it was cast in.
A10: 9
A11: 10
A12: 11
A13: 12
A14: 13 | F14: Replaces High Alert (adds protection/finisher/threat). Evidence: the card it replaces was cast in 89% of the games it was drawn; sat dead in hand 11% of the time; landed on turn 8.2 on average; the deck won 24% of games it was cast in. | I14: Replaces Seaside Citadel (adds draw/removal/protection/threat). Evidence: the land it replaces carried no spell effect the model could use; it was drawn in 19% of games; the deck stayed inside its land floor after the cut. | J14: Replaces Evolving Wilds (adds removal/protection). Evidence: the land it replaces carried no spell effect the model could use; it was drawn in 18% of games; the deck stayed inside its land floor after the cut.
A15: 14
A16: 15
A17: 16
A18: 17
A19: 18
A20: 19
A21: 20
A22: 21 | I22: Replaces Selesnya Sanctuary (adds draw/removal/protection). Evidence: the land it replaces carried no spell effect the model could use; it was drawn in 19% of games; the deck stayed inside its land floor after the cut. | J22: Replaces Krosan Verge (adds removal/protection). Evidence: the land it replaces carried no spell effect the model could use; it was drawn in 19% of games; the deck stayed inside its land floor after the cut.
A23: 22
A24: 23
A25: 24
A26: 25
A27: 26
A28: 27
A29: 28
A30: 29
A31: 30
A32: 31
A33: 32 | F33: Replaces Return to Dust (adds removal/finisher/threat). Evidence: the card it replaces was cast in 85% of the games it was drawn; sat dead in hand 15% of the time; landed on turn 8.6 on average; the deck won 22% of games it was cast in.
A34: 33
A35: 34
A36: 35 | I36: Replaces Sunpetal Grove (adds removal/protection). Evidence: the land it replaces carried no spell effect the model could use; it was drawn in 18% of games; the deck stayed inside its land floor after the cut.
A37: 36 | F37: Replaces Mystic Confluence (adds draw/protection/finisher/threat). Evidence: the card it replaces was cast in 78% of the games it was drawn; sat dead in hand 22% of the time; landed on turn 8.1 on average; the deck won 23% of games it was cast in.
A38: 37
A39: 38
A40: 39
...

Sheet 5o Lorehold Spirit
A1: Lorehold Spirit — Quintorius, History Chaser
A2: Deck slot 5 · variant 5o · 100 lineup slots · alternative commander tested: Iroas, God of Victory
B4: Site ladder — as published | F4: Simulation-improved (Monte Carlo) | I4: Fun-weighted engine v2.1 | K4: Alternative commander
A5: Slot | B5: Base | C5: Tuned | D5: Enhance | E5: Max | F5: Tuned-2 | G5: Enhance-2 | H5: Max-2 | I5: Fun Tuned | J5: Fun Max | K5: Alt Tuned | L5: Alt Max | M5: FINAL PICK | N5: Final card | O5: Price | P5: Why this card moved
A6: 1 | B6: Quintorius, History Chaser | C6: Quintorius, History Chaser | D6: Quintorius, History Chaser | E6: Quintorius, History Chaser | F6: Quintorius, History Chaser | G6: Quintorius, History Chaser | H6: Quintorius, History Chaser | I6: Quintorius, History Chaser | J6: Quintorius, History Chaser | K6: Iroas, God of Victory | L6: Iroas, God of Victory | M6: Fun Max | N6: =INDEX(B6:L6,MATCH(M6,$B$5:$L$5,0)) | O6: =IFERROR(VLOOKUP(N6,Prices!$A:$B,2,FALSE),0) | P6: =IFERROR(INDEX('_why_5o'!$B2:$L2,MATCH(M6,$B$5:$L$5,0)),"")
A7: 2 | B7: Excava, the Risen Past | C7: Cast Out | D7: Cast Out | E7: Cast Out | F7: Darksteel Plate | G7: Darksteel Plate | H7: Darksteel Plate | I7: Cloud's Limit Break | J7: Venat, Heart of Hydaelyn // Hydaelyn, the Mothercrystal | K7: Cloud's Limit Break | L7: Cloud's Limit Break | M7: Fun Max | N7: =INDEX(B7:L7,MATCH(M7,$B$5:$L$5,0)) | O7: =IFERROR(VLOOKUP(N7,Prices!$A:$B,2,FALSE),0) | P7: =IFERROR(INDEX('_why_5o'!$B3:$L3,MATCH(M7,$B$5:$L$5,0)),"")
A8: 3 | B8: Lorehold Archivist // Restore Relic | C8: Lorehold Archivist // Restore Relic | D8: Lorehold Archivist // Restore Relic | E8: Lorehold Archivist // Restore Relic | F8: Lorehold Archivist // Restore Relic | G8: Lorehold Archivist // Restore Relic | H8: Lorehold Archivist // Restore Relic | I8: Lorehold Archivist // Restore Relic | J8: Lorehold Archivist // Restore Relic | K8: Lorehold Archivist // Restore Relic | L8: Lorehold Archivist // Restore Relic | M8: Fun Max | N8: =INDEX(B8:L8,MATCH(M8,$B$5:$L$5,0)) | O8: =IFERROR(VLOOKUP(N8,Prices!$A:$B,2,FALSE),0) | P8: =IFERROR(INDEX('_why_5o'!$B4:$L4,MATCH(M8,$B$5:$L$5,0)),"")
A9: 4 | B9: Augusta, Order Returned | C9: Augusta, Order Returned | D9: Augusta, Order Returned | E9: Augusta, Order Returned | F9: Augusta, Order Returned | G9: Augusta, Order Returned | H9: Augusta, Order Returned | I9: Augusta, Order Returned | J9: Augusta, Order Returned | K9: Augusta, Order Returned | L9: Augusta, Order Returned | M9: Fun Max | N9: =INDEX(B9:L9,MATCH(M9,$B$5:$L$5,0)) | O9: =IFERROR(VLOOKUP(N9,Prices!$A:$B,2,FALSE),0) | P9: =IFERROR(INDEX('_why_5o'!$B5:$L5,MATCH(M9,$B$5:$L$5,0)),"")
A10: 5 | B10: Ceaseless Conflict | C10: Ceaseless Conflict | D10: Ceaseless Conflict | E10: Ceaseless Conflict | F10: Cloud's Limit Break | G10: Cloud's Limit Break | H10: Cloud's Limit Break | I10: Season of the Burrow | J10: Ceaseless Conflict | K10: Venat, Heart of Hydaelyn // Hydaelyn, the Mothercrystal | L10: Venat, Heart of Hydaelyn // Hydaelyn, the Mothercrystal | M10: Fun Max | N10: =INDEX(B10:L10,MATCH(M10,$B$5:$L$5,0)) | O10: =IFERROR(VLOOKUP(N10,Prices!$A:$B,2,FALSE),0) | P10: =IFERROR(INDEX('_why_5o'!$B6:$L6,MATCH(M10,$B$5:$L$5,0)),"")
A11: 6 | B11: Vanguard of the Restless | C11: Vanguard of the Restless | D11: Vanguard of the Restless | E11: Vanguard of the Restless | F11: Vanguard of the Restless | G11: Vanguard of the Restless | H11: Vanguard of the Restless | I11: Vanguard of the Restless | J11: Vanguard of the Restless | K11: Vanguard of the Restless | L11: Vanguard of the Restless | M11: Fun Max | N11: =INDEX(B11:L11,MATCH(M11,$B$5:$L$5,0)) | O11: =IFERROR(VLOOKUP(N11,Prices!$A:$B,2,FALSE),0) | P11: =IFERROR(INDEX('_why_5o'!$B7:$L7,MATCH(M11,$B$5:$L$5,0)),"")
A12: 7 | B12: Advanced Reconstruction | C12: Portable Hole | D12: Portable Hole | E12: Portable Hole | F12: Cast Out | G12: Cast Out | H12: Cast Out | I12: Venat, Heart of Hydaelyn // Hydaelyn, the Mothercrystal | J12: Pyroblast | K12: Pyroblast | L12: Pyroblast | M12: Fun Max | N12: =INDEX(B12:L12,MATCH(M12,$B$5:$L$5,0)) | O12: =IFERROR(VLOOKUP(N12,Prices!$A:$B,2,FALSE),0) | P12: =IFERROR(INDEX('_why_5o'!$B8:$L8,MATCH(M12,$B$5:$L$5,0)),"")
A13: 8 | B13: Fateful Tempest | C13: Knight of the White Orchid | D13: Bag of Holding | E13: Knight of the White Orchid | F13: Sunforger | G13: Sunforger | H13: Sunforger | I13: Pyroblast | J13: Cathar Commando | K13: Boros Charm | L13: Éowyn, Fearless Knight | M13: Fun Max | N13: =INDEX(B13:L13,MATCH(M13,$B$5:$L$5,0)) | O13: =IFERROR(VLOOKUP(N13,Prices!$A:$B,2,FALSE),0) | P13: =IFERROR(INDEX('_why_5o'!$B9:$L9,MATCH(M13,$B$5:$L$5,0)),"")
